2020-06-21 08:27:06,304 [uWSGIWorker1Core0:139737293428224] [django.db.backends:110] [utils:execute] [DEBUG]- (0.000) SELECT `django_session`.`session_key`, `django_session`.`session_data`, `django_session`.`expire_date` FROM `django_session` WHERE (`django_session`.`expire_date` > '2020-06-21 08:27:06.297504' AND `django_session`.`session_key` = 'b9iwultyte977hm1pqjvmmpc03f8av7g'); args=('2020-06-21 08:27:06.297504', 'b9iwultyte977hm1pqjvmmpc03f8av7g')
2020-06-21 08:27:06,313 [uWSGIWorker1Core0:139737293428224] [django.db.backends:110] [utils:execute] [DEBUG]- (0.003) SELECT `auth_user`.`id`, `auth_user`.`password`, `auth_user`.`last_login`, `auth_user`.`is_superuser`, `auth_user`.`username`, `auth_user`.`first_name`, `auth_user`.`last_name`, `auth_user`.`email`, `auth_user`.`is_staff`, `auth_user`.`is_active`, `auth_user`.`date_joined` FROM `auth_user` WHERE `auth_user`.`id` = 1; args=(1,)
2020-06-21 08:27:06,324 [uWSGIWorker1Core0:139737293428224] [django.template:872] [base:_resolve_lookup] [DEBUG]- Exception while resolving variable 'name' in template 'unknown'.
Traceback (most recent call last):
  File "/root/Envs/haole-uumOUkom/lib/python3.6/site-packages/django/core/handlers/exception.py", line 34, in inner
    response = get_response(request)
  File "/root/Envs/haole-uumOUkom/lib/python3.6/site-packages/django/core/handlers/base.py", line 100, in _get_response
    resolver_match = resolver.resolve(request.path_info)
  File "/root/Envs/haole-uumOUkom/lib/python3.6/site-packages/django/urls/resolvers.py", line 558, in resolve
    raise Resolver404({'tried': tried, 'path': new_path})
django.urls.exceptions.Resolver404: {'tried': [[<URLResolver <URLPattern list> (admin:admin) 'admin/'>], [<URLResolver <module 'apps.home.urls' from './apps/home/urls.py'> (None:None) ''>, <URLPattern '' [name='home']>], [<URLResolver <module 'apps.home.urls' from './apps/home/urls.py'> (None:None) ''>, <URLPattern 'delete' [name='delete']>], [<URLResolver <module 'apps.detail.urls' from './apps/detail/urls.py'> (None:None) 'article/'>], [<URLPattern '^favicon.ico$'>]], 'path': 'template/default_pc/html/style/js/lazyload.min.js'}

During handling of the above exception, another exception occurred:

Traceback (most recent call last):
  File "/root/Envs/haole-uumOUkom/lib/python3.6/site-packages/django/template/base.py", line 829, in _resolve_lookup
    current = current[bit]
TypeError: 'URLResolver' object is not subscriptable

During handling of the above exception, another exception occurred:

Traceback (most recent call last):
  File "/root/Envs/haole-uumOUkom/lib/python3.6/site-packages/django/template/base.py", line 837, in _resolve_lookup
    current = getattr(current, bit)
AttributeError: 'URLResolver' object has no attribute 'name'

During handling of the above exception, another exception occurred:

Traceback (most recent call last):
  File "/root/Envs/haole-uumOUkom/lib/python3.6/site-packages/django/template/base.py", line 843, in _resolve_lookup
    current = current[int(bit)]
ValueError: invalid literal for int() with base 10: 'name'

During handling of the above exception, another exception occurred:

Traceback (most recent call last):
  File "/root/Envs/haole-uumOUkom/lib/python3.6/site-packages/django/template/base.py", line 850, in _resolve_lookup
    (bit, current))  # missing attribute
django.template.base.VariableDoesNotExist: Failed lookup for key [name] in <URLResolver <URLPattern list> (admin:admin) 'admin/'>
2020-06-21 08:27:06,325 [uWSGIWorker1Core0:139737293428224] [django.template:872] [base:_resolve_lookup] [DEBUG]- Exception while resolving variable 'name' in template 'unknown'.
Traceback (most recent call last):
  File "/root/Envs/haole-uumOUkom/lib/python3.6/site-packages/django/core/handlers/exception.py", line 34, in inner
    response = get_response(request)
  File "/root/Envs/haole-uumOUkom/lib/python3.6/site-packages/django/core/handlers/base.py", line 100, in _get_response
    resolver_match = resolver.resolve(request.path_info)
  File "/root/Envs/haole-uumOUkom/lib/python3.6/site-packages/django/urls/resolvers.py", line 558, in resolve
    raise Resolver404({'tried': tried, 'path': new_path})
django.urls.exceptions.Resolver404: {'tried': [[<URLResolver <URLPattern list> (admin:admin) 'admin/'>], [<URLResolver <module 'apps.home.urls' from './apps/home/urls.py'> (None:None) ''>, <URLPattern '' [name='home']>], [<URLResolver <module 'apps.home.urls' from './apps/home/urls.py'> (None:None) ''>, <URLPattern 'delete' [name='delete']>], [<URLResolver <module 'apps.detail.urls' from './apps/detail/urls.py'> (None:None) 'article/'>], [<URLPattern '^favicon.ico$'>]], 'path': 'template/default_pc/html/style/js/lazyload.min.js'}

During handling of the above exception, another exception occurred:

Traceback (most recent call last):
  File "/root/Envs/haole-uumOUkom/lib/python3.6/site-packages/django/template/base.py", line 829, in _resolve_lookup
    current = current[bit]
TypeError: 'URLResolver' object is not subscriptable

During handling of the above exception, another exception occurred:

Traceback (most recent call last):
  File "/root/Envs/haole-uumOUkom/lib/python3.6/site-packages/django/template/base.py", line 837, in _resolve_lookup
    current = getattr(current, bit)
AttributeError: 'URLResolver' object has no attribute 'name'

During handling of the above exception, another exception occurred:

Traceback (most recent call last):
  File "/root/Envs/haole-uumOUkom/lib/python3.6/site-packages/django/template/base.py", line 843, in _resolve_lookup
    current = current[int(bit)]
ValueError: invalid literal for int() with base 10: 'name'

During handling of the above exception, another exception occurred:

Traceback (most recent call last):
  File "/root/Envs/haole-uumOUkom/lib/python3.6/site-packages/django/template/base.py", line 850, in _resolve_lookup
    (bit, current))  # missing attribute
django.template.base.VariableDoesNotExist: Failed lookup for key [name] in <URLResolver <module 'apps.detail.urls' from './apps/detail/urls.py'> (None:None) 'article/'>
2020-06-21 08:27:06,459 [uWSGIWorker1Core0:139737293428224] [django.db.backends:110] [utils:execute] [DEBUG]- (0.000) SET SESSION TRANSACTION ISOLATION LEVEL READ COMMITTED; args=None
2020-06-21 08:27:06,459 [uWSGIWorker1Core0:139737293428224] [django.db.backends:110] [utils:execute] [DEBUG]- (0.000) SELECT `django_session`.`session_key`, `django_session`.`session_data`, `django_session`.`expire_date` FROM `django_session` WHERE (`django_session`.`expire_date` > '2020-06-21 08:27:06.457556' AND `django_session`.`session_key` = 'b9iwultyte977hm1pqjvmmpc03f8av7g'); args=('2020-06-21 08:27:06.457556', 'b9iwultyte977hm1pqjvmmpc03f8av7g')
2020-06-21 08:27:06,461 [uWSGIWorker1Core0:139737293428224] [django.db.backends:110] [utils:execute] [DEBUG]- (0.000) SELECT `auth_user`.`id`, `auth_user`.`password`, `auth_user`.`last_login`, `auth_user`.`is_superuser`, `auth_user`.`username`, `auth_user`.`first_name`, `auth_user`.`last_name`, `auth_user`.`email`, `auth_user`.`is_staff`, `auth_user`.`is_active`, `auth_user`.`date_joined` FROM `auth_user` WHERE `auth_user`.`id` = 1; args=(1,)
2020-06-21 08:27:06,464 [uWSGIWorker1Core0:139737293428224] [django.template:872] [base:_resolve_lookup] [DEBUG]- Exception while resolving variable 'name' in template 'unknown'.
Traceback (most recent call last):
  File "/root/Envs/haole-uumOUkom/lib/python3.6/site-packages/django/core/handlers/exception.py", line 34, in inner
    response = get_response(request)
  File "/root/Envs/haole-uumOUkom/lib/python3.6/site-packages/django/core/handlers/base.py", line 100, in _get_response
    resolver_match = resolver.resolve(request.path_info)
  File "/root/Envs/haole-uumOUkom/lib/python3.6/site-packages/django/urls/resolvers.py", line 558, in resolve
    raise Resolver404({'tried': tried, 'path': new_path})
django.urls.exceptions.Resolver404: {'tried': [[<URLResolver <URLPattern list> (admin:admin) 'admin/'>], [<URLResolver <module 'apps.home.urls' from './apps/home/urls.py'> (None:None) ''>, <URLPattern '' [name='home']>], [<URLResolver <module 'apps.home.urls' from './apps/home/urls.py'> (None:None) ''>, <URLPattern 'delete' [name='delete']>], [<URLResolver <module 'apps.detail.urls' from './apps/detail/urls.py'> (None:None) 'article/'>], [<URLPattern '^favicon.ico$'>]], 'path': 'template/default_pc/html/style/js/bootstrap.min.js'}

During handling of the above exception, another exception occurred:

Traceback (most recent call last):
  File "/root/Envs/haole-uumOUkom/lib/python3.6/site-packages/django/template/base.py", line 829, in _resolve_lookup
    current = current[bit]
TypeError: 'URLResolver' object is not subscriptable

During handling of the above exception, another exception occurred:

Traceback (most recent call last):
  File "/root/Envs/haole-uumOUkom/lib/python3.6/site-packages/django/template/base.py", line 837, in _resolve_lookup
    current = getattr(current, bit)
AttributeError: 'URLResolver' object has no attribute 'name'

During handling of the above exception, another exception occurred:

Traceback (most recent call last):
  File "/root/Envs/haole-uumOUkom/lib/python3.6/site-packages/django/template/base.py", line 843, in _resolve_lookup
    current = current[int(bit)]
ValueError: invalid literal for int() with base 10: 'name'

During handling of the above exception, another exception occurred:

Traceback (most recent call last):
  File "/root/Envs/haole-uumOUkom/lib/python3.6/site-packages/django/template/base.py", line 850, in _resolve_lookup
    (bit, current))  # missing attribute
django.template.base.VariableDoesNotExist: Failed lookup for key [name] in <URLResolver <URLPattern list> (admin:admin) 'admin/'>
2020-06-21 08:27:06,465 [uWSGIWorker1Core0:139737293428224] [django.template:872] [base:_resolve_lookup] [DEBUG]- Exception while resolving variable 'name' in template 'unknown'.
Traceback (most recent call last):
  File "/root/Envs/haole-uumOUkom/lib/python3.6/site-packages/django/core/handlers/exception.py", line 34, in inner
    response = get_response(request)
  File "/root/Envs/haole-uumOUkom/lib/python3.6/site-packages/django/core/handlers/base.py", line 100, in _get_response
    resolver_match = resolver.resolve(request.path_info)
  File "/root/Envs/haole-uumOUkom/lib/python3.6/site-packages/django/urls/resolvers.py", line 558, in resolve
    raise Resolver404({'tried': tried, 'path': new_path})
django.urls.exceptions.Resolver404: {'tried': [[<URLResolver <URLPattern list> (admin:admin) 'admin/'>], [<URLResolver <module 'apps.home.urls' from './apps/home/urls.py'> (None:None) ''>, <URLPattern '' [name='home']>], [<URLResolver <module 'apps.home.urls' from './apps/home/urls.py'> (None:None) ''>, <URLPattern 'delete' [name='delete']>], [<URLResolver <module 'apps.detail.urls' from './apps/detail/urls.py'> (None:None) 'article/'>], [<URLPattern '^favicon.ico$'>]], 'path': 'template/default_pc/html/style/js/bootstrap.min.js'}

During handling of the above exception, another exception occurred:

Traceback (most recent call last):
  File "/root/Envs/haole-uumOUkom/lib/python3.6/site-packages/django/template/base.py", line 829, in _resolve_lookup
    current = current[bit]
TypeError: 'URLResolver' object is not subscriptable

During handling of the above exception, another exception occurred:

Traceback (most recent call last):
  File "/root/Envs/haole-uumOUkom/lib/python3.6/site-packages/django/template/base.py", line 837, in _resolve_lookup
    current = getattr(current, bit)
AttributeError: 'URLResolver' object has no attribute 'name'

During handling of the above exception, another exception occurred:

Traceback (most recent call last):
  File "/root/Envs/haole-uumOUkom/lib/python3.6/site-packages/django/template/base.py", line 843, in _resolve_lookup
    current = current[int(bit)]
ValueError: invalid literal for int() with base 10: 'name'

During handling of the above exception, another exception occurred:

Traceback (most recent call last):
  File "/root/Envs/haole-uumOUkom/lib/python3.6/site-packages/django/template/base.py", line 850, in _resolve_lookup
    (bit, current))  # missing attribute
django.template.base.VariableDoesNotExist: Failed lookup for key [name] in <URLResolver <module 'apps.detail.urls' from './apps/detail/urls.py'> (None:None) 'article/'>
2020-06-21 08:27:06,601 [uWSGIWorker1Core0:139737293428224] [django.db.backends:110] [utils:execute] [DEBUG]- (0.000) SET SESSION TRANSACTION ISOLATION LEVEL READ COMMITTED; args=None
2020-06-21 08:27:06,602 [uWSGIWorker1Core0:139737293428224] [django.db.backends:110] [utils:execute] [DEBUG]- (0.000) SELECT `django_session`.`session_key`, `django_session`.`session_data`, `django_session`.`expire_date` FROM `django_session` WHERE (`django_session`.`expire_date` > '2020-06-21 08:27:06.599756' AND `django_session`.`session_key` = 'b9iwultyte977hm1pqjvmmpc03f8av7g'); args=('2020-06-21 08:27:06.599756', 'b9iwultyte977hm1pqjvmmpc03f8av7g')
2020-06-21 08:27:06,603 [uWSGIWorker1Core0:139737293428224] [django.db.backends:110] [utils:execute] [DEBUG]- (0.000) SELECT `auth_user`.`id`, `auth_user`.`password`, `auth_user`.`last_login`, `auth_user`.`is_superuser`, `auth_user`.`username`, `auth_user`.`first_name`, `auth_user`.`last_name`, `auth_user`.`email`, `auth_user`.`is_staff`, `auth_user`.`is_active`, `auth_user`.`date_joined` FROM `auth_user` WHERE `auth_user`.`id` = 1; args=(1,)
2020-06-21 08:27:06,607 [uWSGIWorker1Core0:139737293428224] [django.template:872] [base:_resolve_lookup] [DEBUG]- Exception while resolving variable 'name' in template 'unknown'.
Traceback (most recent call last):
  File "/root/Envs/haole-uumOUkom/lib/python3.6/site-packages/django/core/handlers/exception.py", line 34, in inner
    response = get_response(request)
  File "/root/Envs/haole-uumOUkom/lib/python3.6/site-packages/django/core/handlers/base.py", line 100, in _get_response
    resolver_match = resolver.resolve(request.path_info)
  File "/root/Envs/haole-uumOUkom/lib/python3.6/site-packages/django/urls/resolvers.py", line 558, in resolve
    raise Resolver404({'tried': tried, 'path': new_path})
django.urls.exceptions.Resolver404: {'tried': [[<URLResolver <URLPattern list> (admin:admin) 'admin/'>], [<URLResolver <module 'apps.home.urls' from './apps/home/urls.py'> (None:None) ''>, <URLPattern '' [name='home']>], [<URLResolver <module 'apps.home.urls' from './apps/home/urls.py'> (None:None) ''>, <URLPattern 'delete' [name='delete']>], [<URLResolver <module 'apps.detail.urls' from './apps/detail/urls.py'> (None:None) 'article/'>], [<URLPattern '^favicon.ico$'>]], 'path': 'template/default_pc/html/style/js/lazyload.min.js'}

During handling of the above exception, another exception occurred:

Traceback (most recent call last):
  File "/root/Envs/haole-uumOUkom/lib/python3.6/site-packages/django/template/base.py", line 829, in _resolve_lookup
    current = current[bit]
TypeError: 'URLResolver' object is not subscriptable

During handling of the above exception, another exception occurred:

Traceback (most recent call last):
  File "/root/Envs/haole-uumOUkom/lib/python3.6/site-packages/django/template/base.py", line 837, in _resolve_lookup
    current = getattr(current, bit)
AttributeError: 'URLResolver' object has no attribute 'name'

During handling of the above exception, another exception occurred:

Traceback (most recent call last):
  File "/root/Envs/haole-uumOUkom/lib/python3.6/site-packages/django/template/base.py", line 843, in _resolve_lookup
    current = current[int(bit)]
ValueError: invalid literal for int() with base 10: 'name'

During handling of the above exception, another exception occurred:

Traceback (most recent call last):
  File "/root/Envs/haole-uumOUkom/lib/python3.6/site-packages/django/template/base.py", line 850, in _resolve_lookup
    (bit, current))  # missing attribute
django.template.base.VariableDoesNotExist: Failed lookup for key [name] in <URLResolver <URLPattern list> (admin:admin) 'admin/'>
2020-06-21 08:27:06,607 [uWSGIWorker1Core0:139737293428224] [django.template:872] [base:_resolve_lookup] [DEBUG]- Exception while resolving variable 'name' in template 'unknown'.
Traceback (most recent call last):
  File "/root/Envs/haole-uumOUkom/lib/python3.6/site-packages/django/core/handlers/exception.py", line 34, in inner
    response = get_response(request)
  File "/root/Envs/haole-uumOUkom/lib/python3.6/site-packages/django/core/handlers/base.py", line 100, in _get_response
    resolver_match = resolver.resolve(request.path_info)
  File "/root/Envs/haole-uumOUkom/lib/python3.6/site-packages/django/urls/resolvers.py", line 558, in resolve
    raise Resolver404({'tried': tried, 'path': new_path})
django.urls.exceptions.Resolver404: {'tried': [[<URLResolver <URLPattern list> (admin:admin) 'admin/'>], [<URLResolver <module 'apps.home.urls' from './apps/home/urls.py'> (None:None) ''>, <URLPattern '' [name='home']>], [<URLResolver <module 'apps.home.urls' from './apps/home/urls.py'> (None:None) ''>, <URLPattern 'delete' [name='delete']>], [<URLResolver <module 'apps.detail.urls' from './apps/detail/urls.py'> (None:None) 'article/'>], [<URLPattern '^favicon.ico$'>]], 'path': 'template/default_pc/html/style/js/lazyload.min.js'}

During handling of the above exception, another exception occurred:

Traceback (most recent call last):
  File "/root/Envs/haole-uumOUkom/lib/python3.6/site-packages/django/template/base.py", line 829, in _resolve_lookup
    current = current[bit]
TypeError: 'URLResolver' object is not subscriptable

During handling of the above exception, another exception occurred:

Traceback (most recent call last):
  File "/root/Envs/haole-uumOUkom/lib/python3.6/site-packages/django/template/base.py", line 837, in _resolve_lookup
    current = getattr(current, bit)
AttributeError: 'URLResolver' object has no attribute 'name'

During handling of the above exception, another exception occurred:

Traceback (most recent call last):
  File "/root/Envs/haole-uumOUkom/lib/python3.6/site-packages/django/template/base.py", line 843, in _resolve_lookup
    current = current[int(bit)]
ValueError: invalid literal for int() with base 10: 'name'

During handling of the above exception, another exception occurred:

Traceback (most recent call last):
  File "/root/Envs/haole-uumOUkom/lib/python3.6/site-packages/django/template/base.py", line 850, in _resolve_lookup
    (bit, current))  # missing attribute
django.template.base.VariableDoesNotExist: Failed lookup for key [name] in <URLResolver <module 'apps.detail.urls' from './apps/detail/urls.py'> (None:None) 'article/'>
2020-06-21 08:27:06,760 [uWSGIWorker1Core0:139737293428224] [django.db.backends:110] [utils:execute] [DEBUG]- (0.000) SET SESSION TRANSACTION ISOLATION LEVEL READ COMMITTED; args=None
2020-06-21 08:27:06,763 [uWSGIWorker1Core0:139737293428224] [django.db.backends:110] [utils:execute] [DEBUG]- (0.000) SELECT `django_session`.`session_key`, `django_session`.`session_data`, `django_session`.`expire_date` FROM `django_session` WHERE (`django_session`.`expire_date` > '2020-06-21 08:27:06.759386' AND `django_session`.`session_key` = 'b9iwultyte977hm1pqjvmmpc03f8av7g'); args=('2020-06-21 08:27:06.759386', 'b9iwultyte977hm1pqjvmmpc03f8av7g')
2020-06-21 08:27:06,764 [uWSGIWorker1Core0:139737293428224] [django.db.backends:110] [utils:execute] [DEBUG]- (0.000) SELECT `auth_user`.`id`, `auth_user`.`password`, `auth_user`.`last_login`, `auth_user`.`is_superuser`, `auth_user`.`username`, `auth_user`.`first_name`, `auth_user`.`last_name`, `auth_user`.`email`, `auth_user`.`is_staff`, `auth_user`.`is_active`, `auth_user`.`date_joined` FROM `auth_user` WHERE `auth_user`.`id` = 1; args=(1,)
2020-06-21 08:27:06,767 [uWSGIWorker1Core0:139737293428224] [django.template:872] [base:_resolve_lookup] [DEBUG]- Exception while resolving variable 'name' in template 'unknown'.
Traceback (most recent call last):
  File "/root/Envs/haole-uumOUkom/lib/python3.6/site-packages/django/core/handlers/exception.py", line 34, in inner
    response = get_response(request)
  File "/root/Envs/haole-uumOUkom/lib/python3.6/site-packages/django/core/handlers/base.py", line 100, in _get_response
    resolver_match = resolver.resolve(request.path_info)
  File "/root/Envs/haole-uumOUkom/lib/python3.6/site-packages/django/urls/resolvers.py", line 558, in resolve
    raise Resolver404({'tried': tried, 'path': new_path})
django.urls.exceptions.Resolver404: {'tried': [[<URLResolver <URLPattern list> (admin:admin) 'admin/'>], [<URLResolver <module 'apps.home.urls' from './apps/home/urls.py'> (None:None) ''>, <URLPattern '' [name='home']>], [<URLResolver <module 'apps.home.urls' from './apps/home/urls.py'> (None:None) ''>, <URLPattern 'delete' [name='delete']>], [<URLResolver <module 'apps.detail.urls' from './apps/detail/urls.py'> (None:None) 'article/'>], [<URLPattern '^favicon.ico$'>]], 'path': 'template/default_pc/html/style/js/masonry.pkgd.min.js'}

During handling of the above exception, another exception occurred:

Traceback (most recent call last):
  File "/root/Envs/haole-uumOUkom/lib/python3.6/site-packages/django/template/base.py", line 829, in _resolve_lookup
    current = current[bit]
TypeError: 'URLResolver' object is not subscriptable

During handling of the above exception, another exception occurred:

Traceback (most recent call last):
  File "/root/Envs/haole-uumOUkom/lib/python3.6/site-packages/django/template/base.py", line 837, in _resolve_lookup
    current = getattr(current, bit)
AttributeError: 'URLResolver' object has no attribute 'name'

During handling of the above exception, another exception occurred:

Traceback (most recent call last):
  File "/root/Envs/haole-uumOUkom/lib/python3.6/site-packages/django/template/base.py", line 843, in _resolve_lookup
    current = current[int(bit)]
ValueError: invalid literal for int() with base 10: 'name'

During handling of the above exception, another exception occurred:

Traceback (most recent call last):
  File "/root/Envs/haole-uumOUkom/lib/python3.6/site-packages/django/template/base.py", line 850, in _resolve_lookup
    (bit, current))  # missing attribute
django.template.base.VariableDoesNotExist: Failed lookup for key [name] in <URLResolver <URLPattern list> (admin:admin) 'admin/'>
2020-06-21 08:27:06,768 [uWSGIWorker1Core0:139737293428224] [django.template:872] [base:_resolve_lookup] [DEBUG]- Exception while resolving variable 'name' in template 'unknown'.
Traceback (most recent call last):
  File "/root/Envs/haole-uumOUkom/lib/python3.6/site-packages/django/core/handlers/exception.py", line 34, in inner
    response = get_response(request)
  File "/root/Envs/haole-uumOUkom/lib/python3.6/site-packages/django/core/handlers/base.py", line 100, in _get_response
    resolver_match = resolver.resolve(request.path_info)
  File "/root/Envs/haole-uumOUkom/lib/python3.6/site-packages/django/urls/resolvers.py", line 558, in resolve
    raise Resolver404({'tried': tried, 'path': new_path})
django.urls.exceptions.Resolver404: {'tried': [[<URLResolver <URLPattern list> (admin:admin) 'admin/'>], [<URLResolver <module 'apps.home.urls' from './apps/home/urls.py'> (None:None) ''>, <URLPattern '' [name='home']>], [<URLResolver <module 'apps.home.urls' from './apps/home/urls.py'> (None:None) ''>, <URLPattern 'delete' [name='delete']>], [<URLResolver <module 'apps.detail.urls' from './apps/detail/urls.py'> (None:None) 'article/'>], [<URLPattern '^favicon.ico$'>]], 'path': 'template/default_pc/html/style/js/masonry.pkgd.min.js'}

During handling of the above exception, another exception occurred:

Traceback (most recent call last):
  File "/root/Envs/haole-uumOUkom/lib/python3.6/site-packages/django/template/base.py", line 829, in _resolve_lookup
    current = current[bit]
TypeError: 'URLResolver' object is not subscriptable

During handling of the above exception, another exception occurred:

Traceback (most recent call last):
  File "/root/Envs/haole-uumOUkom/lib/python3.6/site-packages/django/template/base.py", line 837, in _resolve_lookup
    current = getattr(current, bit)
AttributeError: 'URLResolver' object has no attribute 'name'

During handling of the above exception, another exception occurred:

Traceback (most recent call last):
  File "/root/Envs/haole-uumOUkom/lib/python3.6/site-packages/django/template/base.py", line 843, in _resolve_lookup
    current = current[int(bit)]
ValueError: invalid literal for int() with base 10: 'name'

During handling of the above exception, another exception occurred:

Traceback (most recent call last):
  File "/root/Envs/haole-uumOUkom/lib/python3.6/site-packages/django/template/base.py", line 850, in _resolve_lookup
    (bit, current))  # missing attribute
django.template.base.VariableDoesNotExist: Failed lookup for key [name] in <URLResolver <module 'apps.detail.urls' from './apps/detail/urls.py'> (None:None) 'article/'>
2020-06-21 08:27:09,358 [uWSGIWorker1Core0:139737293428224] [django.db.backends:110] [utils:execute] [DEBUG]- (0.000) SET SESSION TRANSACTION ISOLATION LEVEL READ COMMITTED; args=None
2020-06-21 08:27:09,359 [uWSGIWorker1Core0:139737293428224] [django.db.backends:110] [utils:execute] [DEBUG]- (0.000) SELECT `django_session`.`session_key`, `django_session`.`session_data`, `django_session`.`expire_date` FROM `django_session` WHERE (`django_session`.`expire_date` > '2020-06-21 08:27:09.357304' AND `django_session`.`session_key` = 'b9iwultyte977hm1pqjvmmpc03f8av7g'); args=('2020-06-21 08:27:09.357304', 'b9iwultyte977hm1pqjvmmpc03f8av7g')
2020-06-21 08:27:09,360 [uWSGIWorker1Core0:139737293428224] [django.db.backends:110] [utils:execute] [DEBUG]- (0.000) SELECT `auth_user`.`id`, `auth_user`.`password`, `auth_user`.`last_login`, `auth_user`.`is_superuser`, `auth_user`.`username`, `auth_user`.`first_name`, `auth_user`.`last_name`, `auth_user`.`email`, `auth_user`.`is_staff`, `auth_user`.`is_active`, `auth_user`.`date_joined` FROM `auth_user` WHERE `auth_user`.`id` = 1; args=(1,)
2020-06-21 08:27:14,685 [uWSGIWorker1Core0:139737293428224] [django.db.backends:110] [utils:execute] [DEBUG]- (0.000) SET SESSION TRANSACTION ISOLATION LEVEL READ COMMITTED; args=None
2020-06-21 08:27:14,688 [uWSGIWorker1Core0:139737293428224] [django.db.backends:110] [utils:execute] [DEBUG]- (0.003) SELECT `django_session`.`session_key`, `django_session`.`session_data`, `django_session`.`expire_date` FROM `django_session` WHERE (`django_session`.`expire_date` > '2020-06-21 08:27:14.680333' AND `django_session`.`session_key` = 'b9iwultyte977hm1pqjvmmpc03f8av7g'); args=('2020-06-21 08:27:14.680333', 'b9iwultyte977hm1pqjvmmpc03f8av7g')
2020-06-21 08:27:14,697 [uWSGIWorker1Core0:139737293428224] [django.db.backends:110] [utils:execute] [DEBUG]- (0.008) SELECT `auth_user`.`id`, `auth_user`.`password`, `auth_user`.`last_login`, `auth_user`.`is_superuser`, `auth_user`.`username`, `auth_user`.`first_name`, `auth_user`.`last_name`, `auth_user`.`email`, `auth_user`.`is_staff`, `auth_user`.`is_active`, `auth_user`.`date_joined` FROM `auth_user` WHERE `auth_user`.`id` = 1; args=(1,)
2020-06-21 08:27:14,710 [uWSGIWorker1Core0:139737293428224] [django.template:872] [base:_resolve_lookup] [DEBUG]- Exception while resolving variable 'name' in template 'unknown'.
Traceback (most recent call last):
  File "/root/Envs/haole-uumOUkom/lib/python3.6/site-packages/django/core/handlers/exception.py", line 34, in inner
    response = get_response(request)
  File "/root/Envs/haole-uumOUkom/lib/python3.6/site-packages/django/core/handlers/base.py", line 100, in _get_response
    resolver_match = resolver.resolve(request.path_info)
  File "/root/Envs/haole-uumOUkom/lib/python3.6/site-packages/django/urls/resolvers.py", line 558, in resolve
    raise Resolver404({'tried': tried, 'path': new_path})
django.urls.exceptions.Resolver404: {'tried': [[<URLResolver <URLPattern list> (admin:admin) 'admin/'>], [<URLResolver <module 'apps.home.urls' from './apps/home/urls.py'> (None:None) ''>, <URLPattern '' [name='home']>], [<URLResolver <module 'apps.home.urls' from './apps/home/urls.py'> (None:None) ''>, <URLPattern 'delete' [name='delete']>], [<URLResolver <module 'apps.detail.urls' from './apps/detail/urls.py'> (None:None) 'article/'>], [<URLPattern '^favicon.ico$'>]], 'path': 'template/default_pc/html/style/js/jquery-3.2.1.slim.min.js'}

During handling of the above exception, another exception occurred:

Traceback (most recent call last):
  File "/root/Envs/haole-uumOUkom/lib/python3.6/site-packages/django/template/base.py", line 829, in _resolve_lookup
    current = current[bit]
TypeError: 'URLResolver' object is not subscriptable

During handling of the above exception, another exception occurred:

Traceback (most recent call last):
  File "/root/Envs/haole-uumOUkom/lib/python3.6/site-packages/django/template/base.py", line 837, in _resolve_lookup
    current = getattr(current, bit)
AttributeError: 'URLResolver' object has no attribute 'name'

During handling of the above exception, another exception occurred:

Traceback (most recent call last):
  File "/root/Envs/haole-uumOUkom/lib/python3.6/site-packages/django/template/base.py", line 843, in _resolve_lookup
    current = current[int(bit)]
ValueError: invalid literal for int() with base 10: 'name'

During handling of the above exception, another exception occurred:

Traceback (most recent call last):
  File "/root/Envs/haole-uumOUkom/lib/python3.6/site-packages/django/template/base.py", line 850, in _resolve_lookup
    (bit, current))  # missing attribute
django.template.base.VariableDoesNotExist: Failed lookup for key [name] in <URLResolver <URLPattern list> (admin:admin) 'admin/'>
2020-06-21 08:27:14,711 [uWSGIWorker1Core0:139737293428224] [django.template:872] [base:_resolve_lookup] [DEBUG]- Exception while resolving variable 'name' in template 'unknown'.
Traceback (most recent call last):
  File "/root/Envs/haole-uumOUkom/lib/python3.6/site-packages/django/core/handlers/exception.py", line 34, in inner
    response = get_response(request)
  File "/root/Envs/haole-uumOUkom/lib/python3.6/site-packages/django/core/handlers/base.py", line 100, in _get_response
    resolver_match = resolver.resolve(request.path_info)
  File "/root/Envs/haole-uumOUkom/lib/python3.6/site-packages/django/urls/resolvers.py", line 558, in resolve
    raise Resolver404({'tried': tried, 'path': new_path})
django.urls.exceptions.Resolver404: {'tried': [[<URLResolver <URLPattern list> (admin:admin) 'admin/'>], [<URLResolver <module 'apps.home.urls' from './apps/home/urls.py'> (None:None) ''>, <URLPattern '' [name='home']>], [<URLResolver <module 'apps.home.urls' from './apps/home/urls.py'> (None:None) ''>, <URLPattern 'delete' [name='delete']>], [<URLResolver <module 'apps.detail.urls' from './apps/detail/urls.py'> (None:None) 'article/'>], [<URLPattern '^favicon.ico$'>]], 'path': 'template/default_pc/html/style/js/jquery-3.2.1.slim.min.js'}

During handling of the above exception, another exception occurred:

Traceback (most recent call last):
  File "/root/Envs/haole-uumOUkom/lib/python3.6/site-packages/django/template/base.py", line 829, in _resolve_lookup
    current = current[bit]
TypeError: 'URLResolver' object is not subscriptable

During handling of the above exception, another exception occurred:

Traceback (most recent call last):
  File "/root/Envs/haole-uumOUkom/lib/python3.6/site-packages/django/template/base.py", line 837, in _resolve_lookup
    current = getattr(current, bit)
AttributeError: 'URLResolver' object has no attribute 'name'

During handling of the above exception, another exception occurred:

Traceback (most recent call last):
  File "/root/Envs/haole-uumOUkom/lib/python3.6/site-packages/django/template/base.py", line 843, in _resolve_lookup
    current = current[int(bit)]
ValueError: invalid literal for int() with base 10: 'name'

During handling of the above exception, another exception occurred:

Traceback (most recent call last):
  File "/root/Envs/haole-uumOUkom/lib/python3.6/site-packages/django/template/base.py", line 850, in _resolve_lookup
    (bit, current))  # missing attribute
django.template.base.VariableDoesNotExist: Failed lookup for key [name] in <URLResolver <module 'apps.detail.urls' from './apps/detail/urls.py'> (None:None) 'article/'>
2020-06-21 08:27:14,765 [uWSGIWorker1Core0:139737293428224] [django.db.backends:110] [utils:execute] [DEBUG]- (0.001) SET SESSION TRANSACTION ISOLATION LEVEL READ COMMITTED; args=None
2020-06-21 08:27:14,767 [uWSGIWorker1Core0:139737293428224] [django.db.backends:110] [utils:execute] [DEBUG]- (0.001) SELECT `django_session`.`session_key`, `django_session`.`session_data`, `django_session`.`expire_date` FROM `django_session` WHERE (`django_session`.`expire_date` > '2020-06-21 08:27:14.761885' AND `django_session`.`session_key` = 'b9iwultyte977hm1pqjvmmpc03f8av7g'); args=('2020-06-21 08:27:14.761885', 'b9iwultyte977hm1pqjvmmpc03f8av7g')
2020-06-21 08:27:14,772 [uWSGIWorker1Core0:139737293428224] [django.db.backends:110] [utils:execute] [DEBUG]- (0.004) SELECT `auth_user`.`id`, `auth_user`.`password`, `auth_user`.`last_login`, `auth_user`.`is_superuser`, `auth_user`.`username`, `auth_user`.`first_name`, `auth_user`.`last_name`, `auth_user`.`email`, `auth_user`.`is_staff`, `auth_user`.`is_active`, `auth_user`.`date_joined` FROM `auth_user` WHERE `auth_user`.`id` = 1; args=(1,)
2020-06-21 08:27:14,782 [uWSGIWorker1Core0:139737293428224] [django.template:872] [base:_resolve_lookup] [DEBUG]- Exception while resolving variable 'name' in template 'unknown'.
Traceback (most recent call last):
  File "/root/Envs/haole-uumOUkom/lib/python3.6/site-packages/django/core/handlers/exception.py", line 34, in inner
    response = get_response(request)
  File "/root/Envs/haole-uumOUkom/lib/python3.6/site-packages/django/core/handlers/base.py", line 100, in _get_response
    resolver_match = resolver.resolve(request.path_info)
  File "/root/Envs/haole-uumOUkom/lib/python3.6/site-packages/django/urls/resolvers.py", line 558, in resolve
    raise Resolver404({'tried': tried, 'path': new_path})
django.urls.exceptions.Resolver404: {'tried': [[<URLResolver <URLPattern list> (admin:admin) 'admin/'>], [<URLResolver <module 'apps.home.urls' from './apps/home/urls.py'> (None:None) ''>, <URLPattern '' [name='home']>], [<URLResolver <module 'apps.home.urls' from './apps/home/urls.py'> (None:None) ''>, <URLPattern 'delete' [name='delete']>], [<URLResolver <module 'apps.detail.urls' from './apps/detail/urls.py'> (None:None) 'article/'>], [<URLPattern '^favicon.ico$'>]], 'path': 'template/default_pc/html/style/js/lazyload.min.js'}

During handling of the above exception, another exception occurred:

Traceback (most recent call last):
  File "/root/Envs/haole-uumOUkom/lib/python3.6/site-packages/django/template/base.py", line 829, in _resolve_lookup
    current = current[bit]
TypeError: 'URLResolver' object is not subscriptable

During handling of the above exception, another exception occurred:

Traceback (most recent call last):
  File "/root/Envs/haole-uumOUkom/lib/python3.6/site-packages/django/template/base.py", line 837, in _resolve_lookup
    current = getattr(current, bit)
AttributeError: 'URLResolver' object has no attribute 'name'

During handling of the above exception, another exception occurred:

Traceback (most recent call last):
  File "/root/Envs/haole-uumOUkom/lib/python3.6/site-packages/django/template/base.py", line 843, in _resolve_lookup
    current = current[int(bit)]
ValueError: invalid literal for int() with base 10: 'name'

During handling of the above exception, another exception occurred:

Traceback (most recent call last):
  File "/root/Envs/haole-uumOUkom/lib/python3.6/site-packages/django/template/base.py", line 850, in _resolve_lookup
    (bit, current))  # missing attribute
django.template.base.VariableDoesNotExist: Failed lookup for key [name] in <URLResolver <URLPattern list> (admin:admin) 'admin/'>
2020-06-21 08:27:14,783 [uWSGIWorker1Core0:139737293428224] [django.template:872] [base:_resolve_lookup] [DEBUG]- Exception while resolving variable 'name' in template 'unknown'.
Traceback (most recent call last):
  File "/root/Envs/haole-uumOUkom/lib/python3.6/site-packages/django/core/handlers/exception.py", line 34, in inner
    response = get_response(request)
  File "/root/Envs/haole-uumOUkom/lib/python3.6/site-packages/django/core/handlers/base.py", line 100, in _get_response
    resolver_match = resolver.resolve(request.path_info)
  File "/root/Envs/haole-uumOUkom/lib/python3.6/site-packages/django/urls/resolvers.py", line 558, in resolve
    raise Resolver404({'tried': tried, 'path': new_path})
django.urls.exceptions.Resolver404: {'tried': [[<URLResolver <URLPattern list> (admin:admin) 'admin/'>], [<URLResolver <module 'apps.home.urls' from './apps/home/urls.py'> (None:None) ''>, <URLPattern '' [name='home']>], [<URLResolver <module 'apps.home.urls' from './apps/home/urls.py'> (None:None) ''>, <URLPattern 'delete' [name='delete']>], [<URLResolver <module 'apps.detail.urls' from './apps/detail/urls.py'> (None:None) 'article/'>], [<URLPattern '^favicon.ico$'>]], 'path': 'template/default_pc/html/style/js/lazyload.min.js'}

During handling of the above exception, another exception occurred:

Traceback (most recent call last):
  File "/root/Envs/haole-uumOUkom/lib/python3.6/site-packages/django/template/base.py", line 829, in _resolve_lookup
    current = current[bit]
TypeError: 'URLResolver' object is not subscriptable

During handling of the above exception, another exception occurred:

Traceback (most recent call last):
  File "/root/Envs/haole-uumOUkom/lib/python3.6/site-packages/django/template/base.py", line 837, in _resolve_lookup
    current = getattr(current, bit)
AttributeError: 'URLResolver' object has no attribute 'name'

During handling of the above exception, another exception occurred:

Traceback (most recent call last):
  File "/root/Envs/haole-uumOUkom/lib/python3.6/site-packages/django/template/base.py", line 843, in _resolve_lookup
    current = current[int(bit)]
ValueError: invalid literal for int() with base 10: 'name'

During handling of the above exception, another exception occurred:

Traceback (most recent call last):
  File "/root/Envs/haole-uumOUkom/lib/python3.6/site-packages/django/template/base.py", line 850, in _resolve_lookup
    (bit, current))  # missing attribute
django.template.base.VariableDoesNotExist: Failed lookup for key [name] in <URLResolver <module 'apps.detail.urls' from './apps/detail/urls.py'> (None:None) 'article/'>
2020-06-21 08:27:14,934 [uWSGIWorker1Core0:139737293428224] [django.db.backends:110] [utils:execute] [DEBUG]- (0.000) SET SESSION TRANSACTION ISOLATION LEVEL READ COMMITTED; args=None
2020-06-21 08:27:14,935 [uWSGIWorker1Core0:139737293428224] [django.db.backends:110] [utils:execute] [DEBUG]- (0.000) SELECT `django_session`.`session_key`, `django_session`.`session_data`, `django_session`.`expire_date` FROM `django_session` WHERE (`django_session`.`expire_date` > '2020-06-21 08:27:14.933068' AND `django_session`.`session_key` = 'b9iwultyte977hm1pqjvmmpc03f8av7g'); args=('2020-06-21 08:27:14.933068', 'b9iwultyte977hm1pqjvmmpc03f8av7g')
2020-06-21 08:27:14,936 [uWSGIWorker1Core0:139737293428224] [django.db.backends:110] [utils:execute] [DEBUG]- (0.000) SELECT `auth_user`.`id`, `auth_user`.`password`, `auth_user`.`last_login`, `auth_user`.`is_superuser`, `auth_user`.`username`, `auth_user`.`first_name`, `auth_user`.`last_name`, `auth_user`.`email`, `auth_user`.`is_staff`, `auth_user`.`is_active`, `auth_user`.`date_joined` FROM `auth_user` WHERE `auth_user`.`id` = 1; args=(1,)
2020-06-21 08:27:14,939 [uWSGIWorker1Core0:139737293428224] [django.template:872] [base:_resolve_lookup] [DEBUG]- Exception while resolving variable 'name' in template 'unknown'.
Traceback (most recent call last):
  File "/root/Envs/haole-uumOUkom/lib/python3.6/site-packages/django/core/handlers/exception.py", line 34, in inner
    response = get_response(request)
  File "/root/Envs/haole-uumOUkom/lib/python3.6/site-packages/django/core/handlers/base.py", line 100, in _get_response
    resolver_match = resolver.resolve(request.path_info)
  File "/root/Envs/haole-uumOUkom/lib/python3.6/site-packages/django/urls/resolvers.py", line 558, in resolve
    raise Resolver404({'tried': tried, 'path': new_path})
django.urls.exceptions.Resolver404: {'tried': [[<URLResolver <URLPattern list> (admin:admin) 'admin/'>], [<URLResolver <module 'apps.home.urls' from './apps/home/urls.py'> (None:None) ''>, <URLPattern '' [name='home']>], [<URLResolver <module 'apps.home.urls' from './apps/home/urls.py'> (None:None) ''>, <URLPattern 'delete' [name='delete']>], [<URLResolver <module 'apps.detail.urls' from './apps/detail/urls.py'> (None:None) 'article/'>], [<URLPattern '^favicon.ico$'>]], 'path': 'template/default_pc/html/style/js/popper.min.js'}

During handling of the above exception, another exception occurred:

Traceback (most recent call last):
  File "/root/Envs/haole-uumOUkom/lib/python3.6/site-packages/django/template/base.py", line 829, in _resolve_lookup
    current = current[bit]
TypeError: 'URLResolver' object is not subscriptable

During handling of the above exception, another exception occurred:

Traceback (most recent call last):
  File "/root/Envs/haole-uumOUkom/lib/python3.6/site-packages/django/template/base.py", line 837, in _resolve_lookup
    current = getattr(current, bit)
AttributeError: 'URLResolver' object has no attribute 'name'

During handling of the above exception, another exception occurred:

Traceback (most recent call last):
  File "/root/Envs/haole-uumOUkom/lib/python3.6/site-packages/django/template/base.py", line 843, in _resolve_lookup
    current = current[int(bit)]
ValueError: invalid literal for int() with base 10: 'name'

During handling of the above exception, another exception occurred:

Traceback (most recent call last):
  File "/root/Envs/haole-uumOUkom/lib/python3.6/site-packages/django/template/base.py", line 850, in _resolve_lookup
    (bit, current))  # missing attribute
django.template.base.VariableDoesNotExist: Failed lookup for key [name] in <URLResolver <URLPattern list> (admin:admin) 'admin/'>
2020-06-21 08:27:14,939 [uWSGIWorker1Core0:139737293428224] [django.template:872] [base:_resolve_lookup] [DEBUG]- Exception while resolving variable 'name' in template 'unknown'.
Traceback (most recent call last):
  File "/root/Envs/haole-uumOUkom/lib/python3.6/site-packages/django/core/handlers/exception.py", line 34, in inner
    response = get_response(request)
  File "/root/Envs/haole-uumOUkom/lib/python3.6/site-packages/django/core/handlers/base.py", line 100, in _get_response
    resolver_match = resolver.resolve(request.path_info)
  File "/root/Envs/haole-uumOUkom/lib/python3.6/site-packages/django/urls/resolvers.py", line 558, in resolve
    raise Resolver404({'tried': tried, 'path': new_path})
django.urls.exceptions.Resolver404: {'tried': [[<URLResolver <URLPattern list> (admin:admin) 'admin/'>], [<URLResolver <module 'apps.home.urls' from './apps/home/urls.py'> (None:None) ''>, <URLPattern '' [name='home']>], [<URLResolver <module 'apps.home.urls' from './apps/home/urls.py'> (None:None) ''>, <URLPattern 'delete' [name='delete']>], [<URLResolver <module 'apps.detail.urls' from './apps/detail/urls.py'> (None:None) 'article/'>], [<URLPattern '^favicon.ico$'>]], 'path': 'template/default_pc/html/style/js/popper.min.js'}

During handling of the above exception, another exception occurred:

Traceback (most recent call last):
  File "/root/Envs/haole-uumOUkom/lib/python3.6/site-packages/django/template/base.py", line 829, in _resolve_lookup
    current = current[bit]
TypeError: 'URLResolver' object is not subscriptable

During handling of the above exception, another exception occurred:

Traceback (most recent call last):
  File "/root/Envs/haole-uumOUkom/lib/python3.6/site-packages/django/template/base.py", line 837, in _resolve_lookup
    current = getattr(current, bit)
AttributeError: 'URLResolver' object has no attribute 'name'

During handling of the above exception, another exception occurred:

Traceback (most recent call last):
  File "/root/Envs/haole-uumOUkom/lib/python3.6/site-packages/django/template/base.py", line 843, in _resolve_lookup
    current = current[int(bit)]
ValueError: invalid literal for int() with base 10: 'name'

During handling of the above exception, another exception occurred:

Traceback (most recent call last):
  File "/root/Envs/haole-uumOUkom/lib/python3.6/site-packages/django/template/base.py", line 850, in _resolve_lookup
    (bit, current))  # missing attribute
django.template.base.VariableDoesNotExist: Failed lookup for key [name] in <URLResolver <module 'apps.detail.urls' from './apps/detail/urls.py'> (None:None) 'article/'>
2020-06-21 08:27:15,081 [uWSGIWorker1Core0:139737293428224] [django.db.backends:110] [utils:execute] [DEBUG]- (0.000) SET SESSION TRANSACTION ISOLATION LEVEL READ COMMITTED; args=None
2020-06-21 08:27:15,082 [uWSGIWorker1Core0:139737293428224] [django.db.backends:110] [utils:execute] [DEBUG]- (0.000) SELECT `django_session`.`session_key`, `django_session`.`session_data`, `django_session`.`expire_date` FROM `django_session` WHERE (`django_session`.`expire_date` > '2020-06-21 08:27:15.080292' AND `django_session`.`session_key` = 'b9iwultyte977hm1pqjvmmpc03f8av7g'); args=('2020-06-21 08:27:15.080292', 'b9iwultyte977hm1pqjvmmpc03f8av7g')
2020-06-21 08:27:15,084 [uWSGIWorker1Core0:139737293428224] [django.db.backends:110] [utils:execute] [DEBUG]- (0.000) SELECT `auth_user`.`id`, `auth_user`.`password`, `auth_user`.`last_login`, `auth_user`.`is_superuser`, `auth_user`.`username`, `auth_user`.`first_name`, `auth_user`.`last_name`, `auth_user`.`email`, `auth_user`.`is_staff`, `auth_user`.`is_active`, `auth_user`.`date_joined` FROM `auth_user` WHERE `auth_user`.`id` = 1; args=(1,)
2020-06-21 08:27:15,087 [uWSGIWorker1Core0:139737293428224] [django.template:872] [base:_resolve_lookup] [DEBUG]- Exception while resolving variable 'name' in template 'unknown'.
Traceback (most recent call last):
  File "/root/Envs/haole-uumOUkom/lib/python3.6/site-packages/django/core/handlers/exception.py", line 34, in inner
    response = get_response(request)
  File "/root/Envs/haole-uumOUkom/lib/python3.6/site-packages/django/core/handlers/base.py", line 100, in _get_response
    resolver_match = resolver.resolve(request.path_info)
  File "/root/Envs/haole-uumOUkom/lib/python3.6/site-packages/django/urls/resolvers.py", line 558, in resolve
    raise Resolver404({'tried': tried, 'path': new_path})
django.urls.exceptions.Resolver404: {'tried': [[<URLResolver <URLPattern list> (admin:admin) 'admin/'>], [<URLResolver <module 'apps.home.urls' from './apps/home/urls.py'> (None:None) ''>, <URLPattern '' [name='home']>], [<URLResolver <module 'apps.home.urls' from './apps/home/urls.py'> (None:None) ''>, <URLPattern 'delete' [name='delete']>], [<URLResolver <module 'apps.detail.urls' from './apps/detail/urls.py'> (None:None) 'article/'>], [<URLPattern '^favicon.ico$'>]], 'path': 'template/default_pc/html/style/js/bootstrap-paginator.js'}

During handling of the above exception, another exception occurred:

Traceback (most recent call last):
  File "/root/Envs/haole-uumOUkom/lib/python3.6/site-packages/django/template/base.py", line 829, in _resolve_lookup
    current = current[bit]
TypeError: 'URLResolver' object is not subscriptable

During handling of the above exception, another exception occurred:

Traceback (most recent call last):
  File "/root/Envs/haole-uumOUkom/lib/python3.6/site-packages/django/template/base.py", line 837, in _resolve_lookup
    current = getattr(current, bit)
AttributeError: 'URLResolver' object has no attribute 'name'

During handling of the above exception, another exception occurred:

Traceback (most recent call last):
  File "/root/Envs/haole-uumOUkom/lib/python3.6/site-packages/django/template/base.py", line 843, in _resolve_lookup
    current = current[int(bit)]
ValueError: invalid literal for int() with base 10: 'name'

During handling of the above exception, another exception occurred:

Traceback (most recent call last):
  File "/root/Envs/haole-uumOUkom/lib/python3.6/site-packages/django/template/base.py", line 850, in _resolve_lookup
    (bit, current))  # missing attribute
django.template.base.VariableDoesNotExist: Failed lookup for key [name] in <URLResolver <URLPattern list> (admin:admin) 'admin/'>
2020-06-21 08:27:15,088 [uWSGIWorker1Core0:139737293428224] [django.template:872] [base:_resolve_lookup] [DEBUG]- Exception while resolving variable 'name' in template 'unknown'.
Traceback (most recent call last):
  File "/root/Envs/haole-uumOUkom/lib/python3.6/site-packages/django/core/handlers/exception.py", line 34, in inner
    response = get_response(request)
  File "/root/Envs/haole-uumOUkom/lib/python3.6/site-packages/django/core/handlers/base.py", line 100, in _get_response
    resolver_match = resolver.resolve(request.path_info)
  File "/root/Envs/haole-uumOUkom/lib/python3.6/site-packages/django/urls/resolvers.py", line 558, in resolve
    raise Resolver404({'tried': tried, 'path': new_path})
django.urls.exceptions.Resolver404: {'tried': [[<URLResolver <URLPattern list> (admin:admin) 'admin/'>], [<URLResolver <module 'apps.home.urls' from './apps/home/urls.py'> (None:None) ''>, <URLPattern '' [name='home']>], [<URLResolver <module 'apps.home.urls' from './apps/home/urls.py'> (None:None) ''>, <URLPattern 'delete' [name='delete']>], [<URLResolver <module 'apps.detail.urls' from './apps/detail/urls.py'> (None:None) 'article/'>], [<URLPattern '^favicon.ico$'>]], 'path': 'template/default_pc/html/style/js/bootstrap-paginator.js'}

During handling of the above exception, another exception occurred:

Traceback (most recent call last):
  File "/root/Envs/haole-uumOUkom/lib/python3.6/site-packages/django/template/base.py", line 829, in _resolve_lookup
    current = current[bit]
TypeError: 'URLResolver' object is not subscriptable

During handling of the above exception, another exception occurred:

Traceback (most recent call last):
  File "/root/Envs/haole-uumOUkom/lib/python3.6/site-packages/django/template/base.py", line 837, in _resolve_lookup
    current = getattr(current, bit)
AttributeError: 'URLResolver' object has no attribute 'name'

During handling of the above exception, another exception occurred:

Traceback (most recent call last):
  File "/root/Envs/haole-uumOUkom/lib/python3.6/site-packages/django/template/base.py", line 843, in _resolve_lookup
    current = current[int(bit)]
ValueError: invalid literal for int() with base 10: 'name'

During handling of the above exception, another exception occurred:

Traceback (most recent call last):
  File "/root/Envs/haole-uumOUkom/lib/python3.6/site-packages/django/template/base.py", line 850, in _resolve_lookup
    (bit, current))  # missing attribute
django.template.base.VariableDoesNotExist: Failed lookup for key [name] in <URLResolver <module 'apps.detail.urls' from './apps/detail/urls.py'> (None:None) 'article/'>
2020-06-21 08:27:15,270 [uWSGIWorker1Core0:139737293428224] [django.db.backends:110] [utils:execute] [DEBUG]- (0.000) SET SESSION TRANSACTION ISOLATION LEVEL READ COMMITTED; args=None
2020-06-21 08:27:15,270 [uWSGIWorker1Core0:139737293428224] [django.db.backends:110] [utils:execute] [DEBUG]- (0.000) SELECT `django_session`.`session_key`, `django_session`.`session_data`, `django_session`.`expire_date` FROM `django_session` WHERE (`django_session`.`expire_date` > '2020-06-21 08:27:15.269010' AND `django_session`.`session_key` = 'b9iwultyte977hm1pqjvmmpc03f8av7g'); args=('2020-06-21 08:27:15.269010', 'b9iwultyte977hm1pqjvmmpc03f8av7g')
2020-06-21 08:27:15,271 [uWSGIWorker1Core0:139737293428224] [django.db.backends:110] [utils:execute] [DEBUG]- (0.000) SELECT `auth_user`.`id`, `auth_user`.`password`, `auth_user`.`last_login`, `auth_user`.`is_superuser`, `auth_user`.`username`, `auth_user`.`first_name`, `auth_user`.`last_name`, `auth_user`.`email`, `auth_user`.`is_staff`, `auth_user`.`is_active`, `auth_user`.`date_joined` FROM `auth_user` WHERE `auth_user`.`id` = 1; args=(1,)
2020-06-21 08:27:15,274 [uWSGIWorker1Core0:139737293428224] [django.template:872] [base:_resolve_lookup] [DEBUG]- Exception while resolving variable 'name' in template 'unknown'.
Traceback (most recent call last):
  File "/root/Envs/haole-uumOUkom/lib/python3.6/site-packages/django/core/handlers/exception.py", line 34, in inner
    response = get_response(request)
  File "/root/Envs/haole-uumOUkom/lib/python3.6/site-packages/django/core/handlers/base.py", line 100, in _get_response
    resolver_match = resolver.resolve(request.path_info)
  File "/root/Envs/haole-uumOUkom/lib/python3.6/site-packages/django/urls/resolvers.py", line 558, in resolve
    raise Resolver404({'tried': tried, 'path': new_path})
django.urls.exceptions.Resolver404: {'tried': [[<URLResolver <URLPattern list> (admin:admin) 'admin/'>], [<URLResolver <module 'apps.home.urls' from './apps/home/urls.py'> (None:None) ''>, <URLPattern '' [name='home']>], [<URLResolver <module 'apps.home.urls' from './apps/home/urls.py'> (None:None) ''>, <URLPattern 'delete' [name='delete']>], [<URLResolver <module 'apps.detail.urls' from './apps/detail/urls.py'> (None:None) 'article/'>], [<URLPattern '^favicon.ico$'>]], 'path': 'template/default_pc/html/style/js/device.js'}

During handling of the above exception, another exception occurred:

Traceback (most recent call last):
  File "/root/Envs/haole-uumOUkom/lib/python3.6/site-packages/django/template/base.py", line 829, in _resolve_lookup
    current = current[bit]
TypeError: 'URLResolver' object is not subscriptable

During handling of the above exception, another exception occurred:

Traceback (most recent call last):
  File "/root/Envs/haole-uumOUkom/lib/python3.6/site-packages/django/template/base.py", line 837, in _resolve_lookup
    current = getattr(current, bit)
AttributeError: 'URLResolver' object has no attribute 'name'

During handling of the above exception, another exception occurred:

Traceback (most recent call last):
  File "/root/Envs/haole-uumOUkom/lib/python3.6/site-packages/django/template/base.py", line 843, in _resolve_lookup
    current = current[int(bit)]
ValueError: invalid literal for int() with base 10: 'name'

During handling of the above exception, another exception occurred:

Traceback (most recent call last):
  File "/root/Envs/haole-uumOUkom/lib/python3.6/site-packages/django/template/base.py", line 850, in _resolve_lookup
    (bit, current))  # missing attribute
django.template.base.VariableDoesNotExist: Failed lookup for key [name] in <URLResolver <URLPattern list> (admin:admin) 'admin/'>
2020-06-21 08:27:15,275 [uWSGIWorker1Core0:139737293428224] [django.template:872] [base:_resolve_lookup] [DEBUG]- Exception while resolving variable 'name' in template 'unknown'.
Traceback (most recent call last):
  File "/root/Envs/haole-uumOUkom/lib/python3.6/site-packages/django/core/handlers/exception.py", line 34, in inner
    response = get_response(request)
  File "/root/Envs/haole-uumOUkom/lib/python3.6/site-packages/django/core/handlers/base.py", line 100, in _get_response
    resolver_match = resolver.resolve(request.path_info)
  File "/root/Envs/haole-uumOUkom/lib/python3.6/site-packages/django/urls/resolvers.py", line 558, in resolve
    raise Resolver404({'tried': tried, 'path': new_path})
django.urls.exceptions.Resolver404: {'tried': [[<URLResolver <URLPattern list> (admin:admin) 'admin/'>], [<URLResolver <module 'apps.home.urls' from './apps/home/urls.py'> (None:None) ''>, <URLPattern '' [name='home']>], [<URLResolver <module 'apps.home.urls' from './apps/home/urls.py'> (None:None) ''>, <URLPattern 'delete' [name='delete']>], [<URLResolver <module 'apps.detail.urls' from './apps/detail/urls.py'> (None:None) 'article/'>], [<URLPattern '^favicon.ico$'>]], 'path': 'template/default_pc/html/style/js/device.js'}

During handling of the above exception, another exception occurred:

Traceback (most recent call last):
  File "/root/Envs/haole-uumOUkom/lib/python3.6/site-packages/django/template/base.py", line 829, in _resolve_lookup
    current = current[bit]
TypeError: 'URLResolver' object is not subscriptable

During handling of the above exception, another exception occurred:

Traceback (most recent call last):
  File "/root/Envs/haole-uumOUkom/lib/python3.6/site-packages/django/template/base.py", line 837, in _resolve_lookup
    current = getattr(current, bit)
AttributeError: 'URLResolver' object has no attribute 'name'

During handling of the above exception, another exception occurred:

Traceback (most recent call last):
  File "/root/Envs/haole-uumOUkom/lib/python3.6/site-packages/django/template/base.py", line 843, in _resolve_lookup
    current = current[int(bit)]
ValueError: invalid literal for int() with base 10: 'name'

During handling of the above exception, another exception occurred:

Traceback (most recent call last):
  File "/root/Envs/haole-uumOUkom/lib/python3.6/site-packages/django/template/base.py", line 850, in _resolve_lookup
    (bit, current))  # missing attribute
django.template.base.VariableDoesNotExist: Failed lookup for key [name] in <URLResolver <module 'apps.detail.urls' from './apps/detail/urls.py'> (None:None) 'article/'>
2020-06-21 08:27:15,423 [uWSGIWorker1Core0:139737293428224] [django.db.backends:110] [utils:execute] [DEBUG]- (0.000) SET SESSION TRANSACTION ISOLATION LEVEL READ COMMITTED; args=None
2020-06-21 08:27:15,423 [uWSGIWorker1Core0:139737293428224] [django.db.backends:110] [utils:execute] [DEBUG]- (0.000) SELECT `django_session`.`session_key`, `django_session`.`session_data`, `django_session`.`expire_date` FROM `django_session` WHERE (`django_session`.`expire_date` > '2020-06-21 08:27:15.421796' AND `django_session`.`session_key` = 'b9iwultyte977hm1pqjvmmpc03f8av7g'); args=('2020-06-21 08:27:15.421796', 'b9iwultyte977hm1pqjvmmpc03f8av7g')
2020-06-21 08:27:15,424 [uWSGIWorker1Core0:139737293428224] [django.db.backends:110] [utils:execute] [DEBUG]- (0.000) SELECT `auth_user`.`id`, `auth_user`.`password`, `auth_user`.`last_login`, `auth_user`.`is_superuser`, `auth_user`.`username`, `auth_user`.`first_name`, `auth_user`.`last_name`, `auth_user`.`email`, `auth_user`.`is_staff`, `auth_user`.`is_active`, `auth_user`.`date_joined` FROM `auth_user` WHERE `auth_user`.`id` = 1; args=(1,)
2020-06-21 08:27:15,427 [uWSGIWorker1Core0:139737293428224] [django.template:872] [base:_resolve_lookup] [DEBUG]- Exception while resolving variable 'name' in template 'unknown'.
Traceback (most recent call last):
  File "/root/Envs/haole-uumOUkom/lib/python3.6/site-packages/django/core/handlers/exception.py", line 34, in inner
    response = get_response(request)
  File "/root/Envs/haole-uumOUkom/lib/python3.6/site-packages/django/core/handlers/base.py", line 100, in _get_response
    resolver_match = resolver.resolve(request.path_info)
  File "/root/Envs/haole-uumOUkom/lib/python3.6/site-packages/django/urls/resolvers.py", line 558, in resolve
    raise Resolver404({'tried': tried, 'path': new_path})
django.urls.exceptions.Resolver404: {'tried': [[<URLResolver <URLPattern list> (admin:admin) 'admin/'>], [<URLResolver <module 'apps.home.urls' from './apps/home/urls.py'> (None:None) ''>, <URLPattern '' [name='home']>], [<URLResolver <module 'apps.home.urls' from './apps/home/urls.py'> (None:None) ''>, <URLPattern 'delete' [name='delete']>], [<URLResolver <module 'apps.detail.urls' from './apps/detail/urls.py'> (None:None) 'article/'>], [<URLPattern '^favicon.ico$'>]], 'path': 'template/default_pc/html/style/js/imagesloaded.pkgd.min.js'}

During handling of the above exception, another exception occurred:

Traceback (most recent call last):
  File "/root/Envs/haole-uumOUkom/lib/python3.6/site-packages/django/template/base.py", line 829, in _resolve_lookup
    current = current[bit]
TypeError: 'URLResolver' object is not subscriptable

During handling of the above exception, another exception occurred:

Traceback (most recent call last):
  File "/root/Envs/haole-uumOUkom/lib/python3.6/site-packages/django/template/base.py", line 837, in _resolve_lookup
    current = getattr(current, bit)
AttributeError: 'URLResolver' object has no attribute 'name'

During handling of the above exception, another exception occurred:

Traceback (most recent call last):
  File "/root/Envs/haole-uumOUkom/lib/python3.6/site-packages/django/template/base.py", line 843, in _resolve_lookup
    current = current[int(bit)]
ValueError: invalid literal for int() with base 10: 'name'

During handling of the above exception, another exception occurred:

Traceback (most recent call last):
  File "/root/Envs/haole-uumOUkom/lib/python3.6/site-packages/django/template/base.py", line 850, in _resolve_lookup
    (bit, current))  # missing attribute
django.template.base.VariableDoesNotExist: Failed lookup for key [name] in <URLResolver <URLPattern list> (admin:admin) 'admin/'>
2020-06-21 08:27:15,427 [uWSGIWorker1Core0:139737293428224] [django.template:872] [base:_resolve_lookup] [DEBUG]- Exception while resolving variable 'name' in template 'unknown'.
Traceback (most recent call last):
  File "/root/Envs/haole-uumOUkom/lib/python3.6/site-packages/django/core/handlers/exception.py", line 34, in inner
    response = get_response(request)
  File "/root/Envs/haole-uumOUkom/lib/python3.6/site-packages/django/core/handlers/base.py", line 100, in _get_response
    resolver_match = resolver.resolve(request.path_info)
  File "/root/Envs/haole-uumOUkom/lib/python3.6/site-packages/django/urls/resolvers.py", line 558, in resolve
    raise Resolver404({'tried': tried, 'path': new_path})
django.urls.exceptions.Resolver404: {'tried': [[<URLResolver <URLPattern list> (admin:admin) 'admin/'>], [<URLResolver <module 'apps.home.urls' from './apps/home/urls.py'> (None:None) ''>, <URLPattern '' [name='home']>], [<URLResolver <module 'apps.home.urls' from './apps/home/urls.py'> (None:None) ''>, <URLPattern 'delete' [name='delete']>], [<URLResolver <module 'apps.detail.urls' from './apps/detail/urls.py'> (None:None) 'article/'>], [<URLPattern '^favicon.ico$'>]], 'path': 'template/default_pc/html/style/js/imagesloaded.pkgd.min.js'}

During handling of the above exception, another exception occurred:

Traceback (most recent call last):
  File "/root/Envs/haole-uumOUkom/lib/python3.6/site-packages/django/template/base.py", line 829, in _resolve_lookup
    current = current[bit]
TypeError: 'URLResolver' object is not subscriptable

During handling of the above exception, another exception occurred:

Traceback (most recent call last):
  File "/root/Envs/haole-uumOUkom/lib/python3.6/site-packages/django/template/base.py", line 837, in _resolve_lookup
    current = getattr(current, bit)
AttributeError: 'URLResolver' object has no attribute 'name'

During handling of the above exception, another exception occurred:

Traceback (most recent call last):
  File "/root/Envs/haole-uumOUkom/lib/python3.6/site-packages/django/template/base.py", line 843, in _resolve_lookup
    current = current[int(bit)]
ValueError: invalid literal for int() with base 10: 'name'

During handling of the above exception, another exception occurred:

Traceback (most recent call last):
  File "/root/Envs/haole-uumOUkom/lib/python3.6/site-packages/django/template/base.py", line 850, in _resolve_lookup
    (bit, current))  # missing attribute
django.template.base.VariableDoesNotExist: Failed lookup for key [name] in <URLResolver <module 'apps.detail.urls' from './apps/detail/urls.py'> (None:None) 'article/'>
2020-06-21 08:27:32,738 [uWSGIWorker1Core0:139737293428224] [django.db.backends:110] [utils:execute] [DEBUG]- (0.000) SET SESSION TRANSACTION ISOLATION LEVEL READ COMMITTED; args=None
2020-06-21 08:27:32,739 [uWSGIWorker1Core0:139737293428224] [django.db.backends:110] [utils:execute] [DEBUG]- (0.000) SELECT `django_session`.`session_key`, `django_session`.`session_data`, `django_session`.`expire_date` FROM `django_session` WHERE (`django_session`.`expire_date` > '2020-06-21 08:27:32.736743' AND `django_session`.`session_key` = 'b9iwultyte977hm1pqjvmmpc03f8av7g'); args=('2020-06-21 08:27:32.736743', 'b9iwultyte977hm1pqjvmmpc03f8av7g')
2020-06-21 08:27:32,741 [uWSGIWorker1Core0:139737293428224] [django.db.backends:110] [utils:execute] [DEBUG]- (0.000) SELECT `auth_user`.`id`, `auth_user`.`password`, `auth_user`.`last_login`, `auth_user`.`is_superuser`, `auth_user`.`username`, `auth_user`.`first_name`, `auth_user`.`last_name`, `auth_user`.`email`, `auth_user`.`is_staff`, `auth_user`.`is_active`, `auth_user`.`date_joined` FROM `auth_user` WHERE `auth_user`.`id` = 1; args=(1,)
2020-06-21 08:27:32,764 [uWSGIWorker1Core0:139737293428224] [django.db.backends:110] [utils:execute] [DEBUG]- (0.020) SELECT `home_article`.`id`, `home_article`.`title`, `home_article`.`content_html`, `home_article`.`add_time`, `home_article`.`platform`, `home_article`.`platform_url`, `home_article`.`status` FROM `home_article` WHERE `home_article`.`id` = 12399; args=(12399,)
2020-06-21 08:27:45,324 [uWSGIWorker1Core0:139737293428224] [django.db.backends:110] [utils:execute] [DEBUG]- (0.000) SET SESSION TRANSACTION ISOLATION LEVEL READ COMMITTED; args=None
2020-06-21 08:27:45,324 [uWSGIWorker1Core0:139737293428224] [django.db.backends:110] [utils:execute] [DEBUG]- (0.000) SELECT `django_session`.`session_key`, `django_session`.`session_data`, `django_session`.`expire_date` FROM `django_session` WHERE (`django_session`.`expire_date` > '2020-06-21 08:27:45.322843' AND `django_session`.`session_key` = 'b9iwultyte977hm1pqjvmmpc03f8av7g'); args=('2020-06-21 08:27:45.322843', 'b9iwultyte977hm1pqjvmmpc03f8av7g')
2020-06-21 08:27:45,325 [uWSGIWorker1Core0:139737293428224] [django.db.backends:110] [utils:execute] [DEBUG]- (0.000) SELECT `auth_user`.`id`, `auth_user`.`password`, `auth_user`.`last_login`, `auth_user`.`is_superuser`, `auth_user`.`username`, `auth_user`.`first_name`, `auth_user`.`last_name`, `auth_user`.`email`, `auth_user`.`is_staff`, `auth_user`.`is_active`, `auth_user`.`date_joined` FROM `auth_user` WHERE `auth_user`.`id` = 1; args=(1,)
2020-06-21 08:27:58,731 [uWSGIWorker1Core0:139737293428224] [django.db.backends:110] [utils:execute] [DEBUG]- (0.000) SET SESSION TRANSACTION ISOLATION LEVEL READ COMMITTED; args=None
2020-06-21 08:27:58,732 [uWSGIWorker1Core0:139737293428224] [django.db.backends:110] [utils:execute] [DEBUG]- (0.000) SELECT `django_session`.`session_key`, `django_session`.`session_data`, `django_session`.`expire_date` FROM `django_session` WHERE (`django_session`.`expire_date` > '2020-06-21 08:27:58.730594' AND `django_session`.`session_key` = 'b9iwultyte977hm1pqjvmmpc03f8av7g'); args=('2020-06-21 08:27:58.730594', 'b9iwultyte977hm1pqjvmmpc03f8av7g')
2020-06-21 08:27:58,733 [uWSGIWorker1Core0:139737293428224] [django.db.backends:110] [utils:execute] [DEBUG]- (0.000) SELECT `auth_user`.`id`, `auth_user`.`password`, `auth_user`.`last_login`, `auth_user`.`is_superuser`, `auth_user`.`username`, `auth_user`.`first_name`, `auth_user`.`last_name`, `auth_user`.`email`, `auth_user`.`is_staff`, `auth_user`.`is_active`, `auth_user`.`date_joined` FROM `auth_user` WHERE `auth_user`.`id` = 1; args=(1,)
2020-06-21 08:28:11,368 [uWSGIWorker1Core0:139737293428224] [django.db.backends:110] [utils:execute] [DEBUG]- (0.000) SET SESSION TRANSACTION ISOLATION LEVEL READ COMMITTED; args=None
2020-06-21 08:28:11,368 [uWSGIWorker1Core0:139737293428224] [django.db.backends:110] [utils:execute] [DEBUG]- (0.000) SELECT `django_session`.`session_key`, `django_session`.`session_data`, `django_session`.`expire_date` FROM `django_session` WHERE (`django_session`.`expire_date` > '2020-06-21 08:28:11.366748' AND `django_session`.`session_key` = 'b9iwultyte977hm1pqjvmmpc03f8av7g'); args=('2020-06-21 08:28:11.366748', 'b9iwultyte977hm1pqjvmmpc03f8av7g')
2020-06-21 08:28:11,370 [uWSGIWorker1Core0:139737293428224] [django.db.backends:110] [utils:execute] [DEBUG]- (0.000) SELECT `auth_user`.`id`, `auth_user`.`password`, `auth_user`.`last_login`, `auth_user`.`is_superuser`, `auth_user`.`username`, `auth_user`.`first_name`, `auth_user`.`last_name`, `auth_user`.`email`, `auth_user`.`is_staff`, `auth_user`.`is_active`, `auth_user`.`date_joined` FROM `auth_user` WHERE `auth_user`.`id` = 1; args=(1,)
2020-06-21 08:28:35,119 [uWSGIWorker1Core0:139737293428224] [django.db.backends:110] [utils:execute] [DEBUG]- (0.000) SET SESSION TRANSACTION ISOLATION LEVEL READ COMMITTED; args=None
2020-06-21 08:28:35,119 [uWSGIWorker1Core0:139737293428224] [django.db.backends:110] [utils:execute] [DEBUG]- (0.000) SELECT `django_session`.`session_key`, `django_session`.`session_data`, `django_session`.`expire_date` FROM `django_session` WHERE (`django_session`.`expire_date` > '2020-06-21 08:28:35.117905' AND `django_session`.`session_key` = 'b9iwultyte977hm1pqjvmmpc03f8av7g'); args=('2020-06-21 08:28:35.117905', 'b9iwultyte977hm1pqjvmmpc03f8av7g')
2020-06-21 08:28:35,120 [uWSGIWorker1Core0:139737293428224] [django.db.backends:110] [utils:execute] [DEBUG]- (0.000) SELECT `auth_user`.`id`, `auth_user`.`password`, `auth_user`.`last_login`, `auth_user`.`is_superuser`, `auth_user`.`username`, `auth_user`.`first_name`, `auth_user`.`last_name`, `auth_user`.`email`, `auth_user`.`is_staff`, `auth_user`.`is_active`, `auth_user`.`date_joined` FROM `auth_user` WHERE `auth_user`.`id` = 1; args=(1,)
2020-06-21 08:28:45,521 [uWSGIWorker1Core0:139737293428224] [django.db.backends:110] [utils:execute] [DEBUG]- (0.000) SET SESSION TRANSACTION ISOLATION LEVEL READ COMMITTED; args=None
2020-06-21 08:28:45,524 [uWSGIWorker1Core0:139737293428224] [django.db.backends:110] [utils:execute] [DEBUG]- (0.000) SELECT `django_session`.`session_key`, `django_session`.`session_data`, `django_session`.`expire_date` FROM `django_session` WHERE (`django_session`.`expire_date` > '2020-06-21 08:28:45.520501' AND `django_session`.`session_key` = 'b9iwultyte977hm1pqjvmmpc03f8av7g'); args=('2020-06-21 08:28:45.520501', 'b9iwultyte977hm1pqjvmmpc03f8av7g')
2020-06-21 08:28:45,526 [uWSGIWorker1Core0:139737293428224] [django.db.backends:110] [utils:execute] [DEBUG]- (0.000) SELECT `auth_user`.`id`, `auth_user`.`password`, `auth_user`.`last_login`, `auth_user`.`is_superuser`, `auth_user`.`username`, `auth_user`.`first_name`, `auth_user`.`last_name`, `auth_user`.`email`, `auth_user`.`is_staff`, `auth_user`.`is_active`, `auth_user`.`date_joined` FROM `auth_user` WHERE `auth_user`.`id` = 1; args=(1,)
2020-06-21 08:28:50,238 [uWSGIWorker1Core0:139737293428224] [django.db.backends:110] [utils:execute] [DEBUG]- (0.000) SET SESSION TRANSACTION ISOLATION LEVEL READ COMMITTED; args=None
2020-06-21 08:28:50,238 [uWSGIWorker1Core0:139737293428224] [django.db.backends:110] [utils:execute] [DEBUG]- (0.000) SELECT `django_session`.`session_key`, `django_session`.`session_data`, `django_session`.`expire_date` FROM `django_session` WHERE (`django_session`.`expire_date` > '2020-06-21 08:28:50.237096' AND `django_session`.`session_key` = 'b9iwultyte977hm1pqjvmmpc03f8av7g'); args=('2020-06-21 08:28:50.237096', 'b9iwultyte977hm1pqjvmmpc03f8av7g')
2020-06-21 08:28:50,240 [uWSGIWorker1Core0:139737293428224] [django.db.backends:110] [utils:execute] [DEBUG]- (0.000) SELECT `auth_user`.`id`, `auth_user`.`password`, `auth_user`.`last_login`, `auth_user`.`is_superuser`, `auth_user`.`username`, `auth_user`.`first_name`, `auth_user`.`last_name`, `auth_user`.`email`, `auth_user`.`is_staff`, `auth_user`.`is_active`, `auth_user`.`date_joined` FROM `auth_user` WHERE `auth_user`.`id` = 1; args=(1,)
2020-06-21 08:29:04,587 [uWSGIWorker1Core0:139737293428224] [django.db.backends:110] [utils:execute] [DEBUG]- (0.000) SET SESSION TRANSACTION ISOLATION LEVEL READ COMMITTED; args=None
2020-06-21 08:29:04,588 [uWSGIWorker1Core0:139737293428224] [django.db.backends:110] [utils:execute] [DEBUG]- (0.000) SELECT `django_session`.`session_key`, `django_session`.`session_data`, `django_session`.`expire_date` FROM `django_session` WHERE (`django_session`.`expire_date` > '2020-06-21 08:29:04.586232' AND `django_session`.`session_key` = 'b9iwultyte977hm1pqjvmmpc03f8av7g'); args=('2020-06-21 08:29:04.586232', 'b9iwultyte977hm1pqjvmmpc03f8av7g')
2020-06-21 08:29:04,589 [uWSGIWorker1Core0:139737293428224] [django.db.backends:110] [utils:execute] [DEBUG]- (0.000) SELECT `auth_user`.`id`, `auth_user`.`password`, `auth_user`.`last_login`, `auth_user`.`is_superuser`, `auth_user`.`username`, `auth_user`.`first_name`, `auth_user`.`last_name`, `auth_user`.`email`, `auth_user`.`is_staff`, `auth_user`.`is_active`, `auth_user`.`date_joined` FROM `auth_user` WHERE `auth_user`.`id` = 1; args=(1,)
2020-06-21 08:29:14,016 [uWSGIWorker1Core0:139737293428224] [django.db.backends:110] [utils:execute] [DEBUG]- (0.000) SET SESSION TRANSACTION ISOLATION LEVEL READ COMMITTED; args=None
2020-06-21 08:29:14,017 [uWSGIWorker1Core0:139737293428224] [django.db.backends:110] [utils:execute] [DEBUG]- (0.000) SELECT `django_session`.`session_key`, `django_session`.`session_data`, `django_session`.`expire_date` FROM `django_session` WHERE (`django_session`.`expire_date` > '2020-06-21 08:29:14.015459' AND `django_session`.`session_key` = 'b9iwultyte977hm1pqjvmmpc03f8av7g'); args=('2020-06-21 08:29:14.015459', 'b9iwultyte977hm1pqjvmmpc03f8av7g')
2020-06-21 08:29:14,018 [uWSGIWorker1Core0:139737293428224] [django.db.backends:110] [utils:execute] [DEBUG]- (0.000) SELECT `auth_user`.`id`, `auth_user`.`password`, `auth_user`.`last_login`, `auth_user`.`is_superuser`, `auth_user`.`username`, `auth_user`.`first_name`, `auth_user`.`last_name`, `auth_user`.`email`, `auth_user`.`is_staff`, `auth_user`.`is_active`, `auth_user`.`date_joined` FROM `auth_user` WHERE `auth_user`.`id` = 1; args=(1,)
2020-06-21 08:29:21,819 [uWSGIWorker1Core0:139737293428224] [django.db.backends:110] [utils:execute] [DEBUG]- (0.000) SET SESSION TRANSACTION ISOLATION LEVEL READ COMMITTED; args=None
2020-06-21 08:29:21,820 [uWSGIWorker1Core0:139737293428224] [django.db.backends:110] [utils:execute] [DEBUG]- (0.000) SELECT `django_session`.`session_key`, `django_session`.`session_data`, `django_session`.`expire_date` FROM `django_session` WHERE (`django_session`.`expire_date` > '2020-06-21 08:29:21.818608' AND `django_session`.`session_key` = 'b9iwultyte977hm1pqjvmmpc03f8av7g'); args=('2020-06-21 08:29:21.818608', 'b9iwultyte977hm1pqjvmmpc03f8av7g')
2020-06-21 08:29:21,821 [uWSGIWorker1Core0:139737293428224] [django.db.backends:110] [utils:execute] [DEBUG]- (0.000) SELECT `auth_user`.`id`, `auth_user`.`password`, `auth_user`.`last_login`, `auth_user`.`is_superuser`, `auth_user`.`username`, `auth_user`.`first_name`, `auth_user`.`last_name`, `auth_user`.`email`, `auth_user`.`is_staff`, `auth_user`.`is_active`, `auth_user`.`date_joined` FROM `auth_user` WHERE `auth_user`.`id` = 1; args=(1,)
2020-06-21 08:29:28,653 [uWSGIWorker1Core0:139737293428224] [django.db.backends:110] [utils:execute] [DEBUG]- (0.000) SET SESSION TRANSACTION ISOLATION LEVEL READ COMMITTED; args=None
2020-06-21 08:29:28,653 [uWSGIWorker1Core0:139737293428224] [django.db.backends:110] [utils:execute] [DEBUG]- (0.000) SELECT `django_session`.`session_key`, `django_session`.`session_data`, `django_session`.`expire_date` FROM `django_session` WHERE (`django_session`.`expire_date` > '2020-06-21 08:29:28.651540' AND `django_session`.`session_key` = 'b9iwultyte977hm1pqjvmmpc03f8av7g'); args=('2020-06-21 08:29:28.651540', 'b9iwultyte977hm1pqjvmmpc03f8av7g')
2020-06-21 08:29:28,655 [uWSGIWorker1Core0:139737293428224] [django.db.backends:110] [utils:execute] [DEBUG]- (0.000) SELECT `auth_user`.`id`, `auth_user`.`password`, `auth_user`.`last_login`, `auth_user`.`is_superuser`, `auth_user`.`username`, `auth_user`.`first_name`, `auth_user`.`last_name`, `auth_user`.`email`, `auth_user`.`is_staff`, `auth_user`.`is_active`, `auth_user`.`date_joined` FROM `auth_user` WHERE `auth_user`.`id` = 1; args=(1,)
