2020-06-21 08:27:06,303 [uWSGIWorker4Core0:139737293428224] [django.db.backends:110] [utils:execute] [DEBUG]- (0.006) SELECT `auth_user`.`id`, `auth_user`.`password`, `auth_user`.`last_login`, `auth_user`.`is_superuser`, `auth_user`.`username`, `auth_user`.`first_name`, `auth_user`.`last_name`, `auth_user`.`email`, `auth_user`.`is_staff`, `auth_user`.`is_active`, `auth_user`.`date_joined` FROM `auth_user` WHERE `auth_user`.`id` = 1; args=(1,)
2020-06-21 08:27:06,309 [uWSGIWorker4Core0:139737293428224] [django.template:872] [base:_resolve_lookup] [DEBUG]- Exception while resolving variable 'name' in template 'unknown'.
Traceback (most recent call last):
  File "/root/Envs/haole-uumOUkom/lib/python3.6/site-packages/django/core/handlers/exception.py", line 34, in inner
    response = get_response(request)
  File "/root/Envs/haole-uumOUkom/lib/python3.6/site-packages/django/core/handlers/base.py", line 100, in _get_response
    resolver_match = resolver.resolve(request.path_info)
  File "/root/Envs/haole-uumOUkom/lib/python3.6/site-packages/django/urls/resolvers.py", line 558, in resolve
    raise Resolver404({'tried': tried, 'path': new_path})
django.urls.exceptions.Resolver404: {'tried': [[<URLResolver <URLPattern list> (admin:admin) 'admin/'>], [<URLResolver <module 'apps.home.urls' from './apps/home/urls.py'> (None:None) ''>, <URLPattern '' [name='home']>], [<URLResolver <module 'apps.home.urls' from './apps/home/urls.py'> (None:None) ''>, <URLPattern 'delete' [name='delete']>], [<URLResolver <module 'apps.detail.urls' from './apps/detail/urls.py'> (None:None) 'article/'>], [<URLPattern '^favicon.ico$'>]], 'path': 'template/default_pc/html/style/js/masonry.pkgd.min.js'}

During handling of the above exception, another exception occurred:

Traceback (most recent call last):
  File "/root/Envs/haole-uumOUkom/lib/python3.6/site-packages/django/template/base.py", line 829, in _resolve_lookup
    current = current[bit]
TypeError: 'URLResolver' object is not subscriptable

During handling of the above exception, another exception occurred:

Traceback (most recent call last):
  File "/root/Envs/haole-uumOUkom/lib/python3.6/site-packages/django/template/base.py", line 837, in _resolve_lookup
    current = getattr(current, bit)
AttributeError: 'URLResolver' object has no attribute 'name'

During handling of the above exception, another exception occurred:

Traceback (most recent call last):
  File "/root/Envs/haole-uumOUkom/lib/python3.6/site-packages/django/template/base.py", line 843, in _resolve_lookup
    current = current[int(bit)]
ValueError: invalid literal for int() with base 10: 'name'

During handling of the above exception, another exception occurred:

Traceback (most recent call last):
  File "/root/Envs/haole-uumOUkom/lib/python3.6/site-packages/django/template/base.py", line 850, in _resolve_lookup
    (bit, current))  # missing attribute
django.template.base.VariableDoesNotExist: Failed lookup for key [name] in <URLResolver <URLPattern list> (admin:admin) 'admin/'>
2020-06-21 08:27:06,321 [uWSGIWorker4Core0:139737293428224] [django.template:872] [base:_resolve_lookup] [DEBUG]- Exception while resolving variable 'name' in template 'unknown'.
Traceback (most recent call last):
  File "/root/Envs/haole-uumOUkom/lib/python3.6/site-packages/django/core/handlers/exception.py", line 34, in inner
    response = get_response(request)
  File "/root/Envs/haole-uumOUkom/lib/python3.6/site-packages/django/core/handlers/base.py", line 100, in _get_response
    resolver_match = resolver.resolve(request.path_info)
  File "/root/Envs/haole-uumOUkom/lib/python3.6/site-packages/django/urls/resolvers.py", line 558, in resolve
    raise Resolver404({'tried': tried, 'path': new_path})
django.urls.exceptions.Resolver404: {'tried': [[<URLResolver <URLPattern list> (admin:admin) 'admin/'>], [<URLResolver <module 'apps.home.urls' from './apps/home/urls.py'> (None:None) ''>, <URLPattern '' [name='home']>], [<URLResolver <module 'apps.home.urls' from './apps/home/urls.py'> (None:None) ''>, <URLPattern 'delete' [name='delete']>], [<URLResolver <module 'apps.detail.urls' from './apps/detail/urls.py'> (None:None) 'article/'>], [<URLPattern '^favicon.ico$'>]], 'path': 'template/default_pc/html/style/js/masonry.pkgd.min.js'}

During handling of the above exception, another exception occurred:

Traceback (most recent call last):
  File "/root/Envs/haole-uumOUkom/lib/python3.6/site-packages/django/template/base.py", line 829, in _resolve_lookup
    current = current[bit]
TypeError: 'URLResolver' object is not subscriptable

During handling of the above exception, another exception occurred:

Traceback (most recent call last):
  File "/root/Envs/haole-uumOUkom/lib/python3.6/site-packages/django/template/base.py", line 837, in _resolve_lookup
    current = getattr(current, bit)
AttributeError: 'URLResolver' object has no attribute 'name'

During handling of the above exception, another exception occurred:

Traceback (most recent call last):
  File "/root/Envs/haole-uumOUkom/lib/python3.6/site-packages/django/template/base.py", line 843, in _resolve_lookup
    current = current[int(bit)]
ValueError: invalid literal for int() with base 10: 'name'

During handling of the above exception, another exception occurred:

Traceback (most recent call last):
  File "/root/Envs/haole-uumOUkom/lib/python3.6/site-packages/django/template/base.py", line 850, in _resolve_lookup
    (bit, current))  # missing attribute
django.template.base.VariableDoesNotExist: Failed lookup for key [name] in <URLResolver <module 'apps.detail.urls' from './apps/detail/urls.py'> (None:None) 'article/'>
2020-06-21 08:27:06,377 [uWSGIWorker4Core0:139737293428224] [django.db.backends:110] [utils:execute] [DEBUG]- (0.000) SET SESSION TRANSACTION ISOLATION LEVEL READ COMMITTED; args=None
2020-06-21 08:27:06,378 [uWSGIWorker4Core0:139737293428224] [django.db.backends:110] [utils:execute] [DEBUG]- (0.000) SELECT `django_session`.`session_key`, `django_session`.`session_data`, `django_session`.`expire_date` FROM `django_session` WHERE (`django_session`.`expire_date` > '2020-06-21 08:27:06.376429' AND `django_session`.`session_key` = 'b9iwultyte977hm1pqjvmmpc03f8av7g'); args=('2020-06-21 08:27:06.376429', 'b9iwultyte977hm1pqjvmmpc03f8av7g')
2020-06-21 08:27:06,379 [uWSGIWorker4Core0:139737293428224] [django.db.backends:110] [utils:execute] [DEBUG]- (0.000) SELECT `auth_user`.`id`, `auth_user`.`password`, `auth_user`.`last_login`, `auth_user`.`is_superuser`, `auth_user`.`username`, `auth_user`.`first_name`, `auth_user`.`last_name`, `auth_user`.`email`, `auth_user`.`is_staff`, `auth_user`.`is_active`, `auth_user`.`date_joined` FROM `auth_user` WHERE `auth_user`.`id` = 1; args=(1,)
2020-06-21 08:27:06,386 [uWSGIWorker4Core0:139737293428224] [django.template:872] [base:_resolve_lookup] [DEBUG]- Exception while resolving variable 'name' in template 'unknown'.
Traceback (most recent call last):
  File "/root/Envs/haole-uumOUkom/lib/python3.6/site-packages/django/core/handlers/exception.py", line 34, in inner
    response = get_response(request)
  File "/root/Envs/haole-uumOUkom/lib/python3.6/site-packages/django/core/handlers/base.py", line 100, in _get_response
    resolver_match = resolver.resolve(request.path_info)
  File "/root/Envs/haole-uumOUkom/lib/python3.6/site-packages/django/urls/resolvers.py", line 558, in resolve
    raise Resolver404({'tried': tried, 'path': new_path})
django.urls.exceptions.Resolver404: {'tried': [[<URLResolver <URLPattern list> (admin:admin) 'admin/'>], [<URLResolver <module 'apps.home.urls' from './apps/home/urls.py'> (None:None) ''>, <URLPattern '' [name='home']>], [<URLResolver <module 'apps.home.urls' from './apps/home/urls.py'> (None:None) ''>, <URLPattern 'delete' [name='delete']>], [<URLResolver <module 'apps.detail.urls' from './apps/detail/urls.py'> (None:None) 'article/'>], [<URLPattern '^favicon.ico$'>]], 'path': 'template/default_pc/html/style/js/bootstrap-paginator.js'}

During handling of the above exception, another exception occurred:

Traceback (most recent call last):
  File "/root/Envs/haole-uumOUkom/lib/python3.6/site-packages/django/template/base.py", line 829, in _resolve_lookup
    current = current[bit]
TypeError: 'URLResolver' object is not subscriptable

During handling of the above exception, another exception occurred:

Traceback (most recent call last):
  File "/root/Envs/haole-uumOUkom/lib/python3.6/site-packages/django/template/base.py", line 837, in _resolve_lookup
    current = getattr(current, bit)
AttributeError: 'URLResolver' object has no attribute 'name'

During handling of the above exception, another exception occurred:

Traceback (most recent call last):
  File "/root/Envs/haole-uumOUkom/lib/python3.6/site-packages/django/template/base.py", line 843, in _resolve_lookup
    current = current[int(bit)]
ValueError: invalid literal for int() with base 10: 'name'

During handling of the above exception, another exception occurred:

Traceback (most recent call last):
  File "/root/Envs/haole-uumOUkom/lib/python3.6/site-packages/django/template/base.py", line 850, in _resolve_lookup
    (bit, current))  # missing attribute
django.template.base.VariableDoesNotExist: Failed lookup for key [name] in <URLResolver <URLPattern list> (admin:admin) 'admin/'>
2020-06-21 08:27:06,387 [uWSGIWorker4Core0:139737293428224] [django.template:872] [base:_resolve_lookup] [DEBUG]- Exception while resolving variable 'name' in template 'unknown'.
Traceback (most recent call last):
  File "/root/Envs/haole-uumOUkom/lib/python3.6/site-packages/django/core/handlers/exception.py", line 34, in inner
    response = get_response(request)
  File "/root/Envs/haole-uumOUkom/lib/python3.6/site-packages/django/core/handlers/base.py", line 100, in _get_response
    resolver_match = resolver.resolve(request.path_info)
  File "/root/Envs/haole-uumOUkom/lib/python3.6/site-packages/django/urls/resolvers.py", line 558, in resolve
    raise Resolver404({'tried': tried, 'path': new_path})
django.urls.exceptions.Resolver404: {'tried': [[<URLResolver <URLPattern list> (admin:admin) 'admin/'>], [<URLResolver <module 'apps.home.urls' from './apps/home/urls.py'> (None:None) ''>, <URLPattern '' [name='home']>], [<URLResolver <module 'apps.home.urls' from './apps/home/urls.py'> (None:None) ''>, <URLPattern 'delete' [name='delete']>], [<URLResolver <module 'apps.detail.urls' from './apps/detail/urls.py'> (None:None) 'article/'>], [<URLPattern '^favicon.ico$'>]], 'path': 'template/default_pc/html/style/js/bootstrap-paginator.js'}

During handling of the above exception, another exception occurred:

Traceback (most recent call last):
  File "/root/Envs/haole-uumOUkom/lib/python3.6/site-packages/django/template/base.py", line 829, in _resolve_lookup
    current = current[bit]
TypeError: 'URLResolver' object is not subscriptable

During handling of the above exception, another exception occurred:

Traceback (most recent call last):
  File "/root/Envs/haole-uumOUkom/lib/python3.6/site-packages/django/template/base.py", line 837, in _resolve_lookup
    current = getattr(current, bit)
AttributeError: 'URLResolver' object has no attribute 'name'

During handling of the above exception, another exception occurred:

Traceback (most recent call last):
  File "/root/Envs/haole-uumOUkom/lib/python3.6/site-packages/django/template/base.py", line 843, in _resolve_lookup
    current = current[int(bit)]
ValueError: invalid literal for int() with base 10: 'name'

During handling of the above exception, another exception occurred:

Traceback (most recent call last):
  File "/root/Envs/haole-uumOUkom/lib/python3.6/site-packages/django/template/base.py", line 850, in _resolve_lookup
    (bit, current))  # missing attribute
django.template.base.VariableDoesNotExist: Failed lookup for key [name] in <URLResolver <module 'apps.detail.urls' from './apps/detail/urls.py'> (None:None) 'article/'>
2020-06-21 08:27:06,526 [uWSGIWorker4Core0:139737293428224] [django.db.backends:110] [utils:execute] [DEBUG]- (0.000) SET SESSION TRANSACTION ISOLATION LEVEL READ COMMITTED; args=None
2020-06-21 08:27:06,526 [uWSGIWorker4Core0:139737293428224] [django.db.backends:110] [utils:execute] [DEBUG]- (0.000) SELECT `django_session`.`session_key`, `django_session`.`session_data`, `django_session`.`expire_date` FROM `django_session` WHERE (`django_session`.`expire_date` > '2020-06-21 08:27:06.525035' AND `django_session`.`session_key` = 'b9iwultyte977hm1pqjvmmpc03f8av7g'); args=('2020-06-21 08:27:06.525035', 'b9iwultyte977hm1pqjvmmpc03f8av7g')
2020-06-21 08:27:06,528 [uWSGIWorker4Core0:139737293428224] [django.db.backends:110] [utils:execute] [DEBUG]- (0.000) SELECT `auth_user`.`id`, `auth_user`.`password`, `auth_user`.`last_login`, `auth_user`.`is_superuser`, `auth_user`.`username`, `auth_user`.`first_name`, `auth_user`.`last_name`, `auth_user`.`email`, `auth_user`.`is_staff`, `auth_user`.`is_active`, `auth_user`.`date_joined` FROM `auth_user` WHERE `auth_user`.`id` = 1; args=(1,)
2020-06-21 08:27:06,531 [uWSGIWorker4Core0:139737293428224] [django.template:872] [base:_resolve_lookup] [DEBUG]- Exception while resolving variable 'name' in template 'unknown'.
Traceback (most recent call last):
  File "/root/Envs/haole-uumOUkom/lib/python3.6/site-packages/django/core/handlers/exception.py", line 34, in inner
    response = get_response(request)
  File "/root/Envs/haole-uumOUkom/lib/python3.6/site-packages/django/core/handlers/base.py", line 100, in _get_response
    resolver_match = resolver.resolve(request.path_info)
  File "/root/Envs/haole-uumOUkom/lib/python3.6/site-packages/django/urls/resolvers.py", line 558, in resolve
    raise Resolver404({'tried': tried, 'path': new_path})
django.urls.exceptions.Resolver404: {'tried': [[<URLResolver <URLPattern list> (admin:admin) 'admin/'>], [<URLResolver <module 'apps.home.urls' from './apps/home/urls.py'> (None:None) ''>, <URLPattern '' [name='home']>], [<URLResolver <module 'apps.home.urls' from './apps/home/urls.py'> (None:None) ''>, <URLPattern 'delete' [name='delete']>], [<URLResolver <module 'apps.detail.urls' from './apps/detail/urls.py'> (None:None) 'article/'>], [<URLPattern '^favicon.ico$'>]], 'path': 'template/default_pc/html/style/js/bootstrap-paginator.js'}

During handling of the above exception, another exception occurred:

Traceback (most recent call last):
  File "/root/Envs/haole-uumOUkom/lib/python3.6/site-packages/django/template/base.py", line 829, in _resolve_lookup
    current = current[bit]
TypeError: 'URLResolver' object is not subscriptable

During handling of the above exception, another exception occurred:

Traceback (most recent call last):
  File "/root/Envs/haole-uumOUkom/lib/python3.6/site-packages/django/template/base.py", line 837, in _resolve_lookup
    current = getattr(current, bit)
AttributeError: 'URLResolver' object has no attribute 'name'

During handling of the above exception, another exception occurred:

Traceback (most recent call last):
  File "/root/Envs/haole-uumOUkom/lib/python3.6/site-packages/django/template/base.py", line 843, in _resolve_lookup
    current = current[int(bit)]
ValueError: invalid literal for int() with base 10: 'name'

During handling of the above exception, another exception occurred:

Traceback (most recent call last):
  File "/root/Envs/haole-uumOUkom/lib/python3.6/site-packages/django/template/base.py", line 850, in _resolve_lookup
    (bit, current))  # missing attribute
django.template.base.VariableDoesNotExist: Failed lookup for key [name] in <URLResolver <URLPattern list> (admin:admin) 'admin/'>
2020-06-21 08:27:06,531 [uWSGIWorker4Core0:139737293428224] [django.template:872] [base:_resolve_lookup] [DEBUG]- Exception while resolving variable 'name' in template 'unknown'.
Traceback (most recent call last):
  File "/root/Envs/haole-uumOUkom/lib/python3.6/site-packages/django/core/handlers/exception.py", line 34, in inner
    response = get_response(request)
  File "/root/Envs/haole-uumOUkom/lib/python3.6/site-packages/django/core/handlers/base.py", line 100, in _get_response
    resolver_match = resolver.resolve(request.path_info)
  File "/root/Envs/haole-uumOUkom/lib/python3.6/site-packages/django/urls/resolvers.py", line 558, in resolve
    raise Resolver404({'tried': tried, 'path': new_path})
django.urls.exceptions.Resolver404: {'tried': [[<URLResolver <URLPattern list> (admin:admin) 'admin/'>], [<URLResolver <module 'apps.home.urls' from './apps/home/urls.py'> (None:None) ''>, <URLPattern '' [name='home']>], [<URLResolver <module 'apps.home.urls' from './apps/home/urls.py'> (None:None) ''>, <URLPattern 'delete' [name='delete']>], [<URLResolver <module 'apps.detail.urls' from './apps/detail/urls.py'> (None:None) 'article/'>], [<URLPattern '^favicon.ico$'>]], 'path': 'template/default_pc/html/style/js/bootstrap-paginator.js'}

During handling of the above exception, another exception occurred:

Traceback (most recent call last):
  File "/root/Envs/haole-uumOUkom/lib/python3.6/site-packages/django/template/base.py", line 829, in _resolve_lookup
    current = current[bit]
TypeError: 'URLResolver' object is not subscriptable

During handling of the above exception, another exception occurred:

Traceback (most recent call last):
  File "/root/Envs/haole-uumOUkom/lib/python3.6/site-packages/django/template/base.py", line 837, in _resolve_lookup
    current = getattr(current, bit)
AttributeError: 'URLResolver' object has no attribute 'name'

During handling of the above exception, another exception occurred:

Traceback (most recent call last):
  File "/root/Envs/haole-uumOUkom/lib/python3.6/site-packages/django/template/base.py", line 843, in _resolve_lookup
    current = current[int(bit)]
ValueError: invalid literal for int() with base 10: 'name'

During handling of the above exception, another exception occurred:

Traceback (most recent call last):
  File "/root/Envs/haole-uumOUkom/lib/python3.6/site-packages/django/template/base.py", line 850, in _resolve_lookup
    (bit, current))  # missing attribute
django.template.base.VariableDoesNotExist: Failed lookup for key [name] in <URLResolver <module 'apps.detail.urls' from './apps/detail/urls.py'> (None:None) 'article/'>
2020-06-21 08:27:06,693 [uWSGIWorker4Core0:139737293428224] [django.db.backends:110] [utils:execute] [DEBUG]- (0.000) SET SESSION TRANSACTION ISOLATION LEVEL READ COMMITTED; args=None
2020-06-21 08:27:06,694 [uWSGIWorker4Core0:139737293428224] [django.db.backends:110] [utils:execute] [DEBUG]- (0.000) SELECT `django_session`.`session_key`, `django_session`.`session_data`, `django_session`.`expire_date` FROM `django_session` WHERE (`django_session`.`expire_date` > '2020-06-21 08:27:06.692263' AND `django_session`.`session_key` = 'b9iwultyte977hm1pqjvmmpc03f8av7g'); args=('2020-06-21 08:27:06.692263', 'b9iwultyte977hm1pqjvmmpc03f8av7g')
2020-06-21 08:27:06,695 [uWSGIWorker4Core0:139737293428224] [django.db.backends:110] [utils:execute] [DEBUG]- (0.000) SELECT `auth_user`.`id`, `auth_user`.`password`, `auth_user`.`last_login`, `auth_user`.`is_superuser`, `auth_user`.`username`, `auth_user`.`first_name`, `auth_user`.`last_name`, `auth_user`.`email`, `auth_user`.`is_staff`, `auth_user`.`is_active`, `auth_user`.`date_joined` FROM `auth_user` WHERE `auth_user`.`id` = 1; args=(1,)
2020-06-21 08:27:06,698 [uWSGIWorker4Core0:139737293428224] [django.template:872] [base:_resolve_lookup] [DEBUG]- Exception while resolving variable 'name' in template 'unknown'.
Traceback (most recent call last):
  File "/root/Envs/haole-uumOUkom/lib/python3.6/site-packages/django/core/handlers/exception.py", line 34, in inner
    response = get_response(request)
  File "/root/Envs/haole-uumOUkom/lib/python3.6/site-packages/django/core/handlers/base.py", line 100, in _get_response
    resolver_match = resolver.resolve(request.path_info)
  File "/root/Envs/haole-uumOUkom/lib/python3.6/site-packages/django/urls/resolvers.py", line 558, in resolve
    raise Resolver404({'tried': tried, 'path': new_path})
django.urls.exceptions.Resolver404: {'tried': [[<URLResolver <URLPattern list> (admin:admin) 'admin/'>], [<URLResolver <module 'apps.home.urls' from './apps/home/urls.py'> (None:None) ''>, <URLPattern '' [name='home']>], [<URLResolver <module 'apps.home.urls' from './apps/home/urls.py'> (None:None) ''>, <URLPattern 'delete' [name='delete']>], [<URLResolver <module 'apps.detail.urls' from './apps/detail/urls.py'> (None:None) 'article/'>], [<URLPattern '^favicon.ico$'>]], 'path': 'template/default_pc/html/style/js/device.js'}

During handling of the above exception, another exception occurred:

Traceback (most recent call last):
  File "/root/Envs/haole-uumOUkom/lib/python3.6/site-packages/django/template/base.py", line 829, in _resolve_lookup
    current = current[bit]
TypeError: 'URLResolver' object is not subscriptable

During handling of the above exception, another exception occurred:

Traceback (most recent call last):
  File "/root/Envs/haole-uumOUkom/lib/python3.6/site-packages/django/template/base.py", line 837, in _resolve_lookup
    current = getattr(current, bit)
AttributeError: 'URLResolver' object has no attribute 'name'

During handling of the above exception, another exception occurred:

Traceback (most recent call last):
  File "/root/Envs/haole-uumOUkom/lib/python3.6/site-packages/django/template/base.py", line 843, in _resolve_lookup
    current = current[int(bit)]
ValueError: invalid literal for int() with base 10: 'name'

During handling of the above exception, another exception occurred:

Traceback (most recent call last):
  File "/root/Envs/haole-uumOUkom/lib/python3.6/site-packages/django/template/base.py", line 850, in _resolve_lookup
    (bit, current))  # missing attribute
django.template.base.VariableDoesNotExist: Failed lookup for key [name] in <URLResolver <URLPattern list> (admin:admin) 'admin/'>
2020-06-21 08:27:06,699 [uWSGIWorker4Core0:139737293428224] [django.template:872] [base:_resolve_lookup] [DEBUG]- Exception while resolving variable 'name' in template 'unknown'.
Traceback (most recent call last):
  File "/root/Envs/haole-uumOUkom/lib/python3.6/site-packages/django/core/handlers/exception.py", line 34, in inner
    response = get_response(request)
  File "/root/Envs/haole-uumOUkom/lib/python3.6/site-packages/django/core/handlers/base.py", line 100, in _get_response
    resolver_match = resolver.resolve(request.path_info)
  File "/root/Envs/haole-uumOUkom/lib/python3.6/site-packages/django/urls/resolvers.py", line 558, in resolve
    raise Resolver404({'tried': tried, 'path': new_path})
django.urls.exceptions.Resolver404: {'tried': [[<URLResolver <URLPattern list> (admin:admin) 'admin/'>], [<URLResolver <module 'apps.home.urls' from './apps/home/urls.py'> (None:None) ''>, <URLPattern '' [name='home']>], [<URLResolver <module 'apps.home.urls' from './apps/home/urls.py'> (None:None) ''>, <URLPattern 'delete' [name='delete']>], [<URLResolver <module 'apps.detail.urls' from './apps/detail/urls.py'> (None:None) 'article/'>], [<URLPattern '^favicon.ico$'>]], 'path': 'template/default_pc/html/style/js/device.js'}

During handling of the above exception, another exception occurred:

Traceback (most recent call last):
  File "/root/Envs/haole-uumOUkom/lib/python3.6/site-packages/django/template/base.py", line 829, in _resolve_lookup
    current = current[bit]
TypeError: 'URLResolver' object is not subscriptable

During handling of the above exception, another exception occurred:

Traceback (most recent call last):
  File "/root/Envs/haole-uumOUkom/lib/python3.6/site-packages/django/template/base.py", line 837, in _resolve_lookup
    current = getattr(current, bit)
AttributeError: 'URLResolver' object has no attribute 'name'

During handling of the above exception, another exception occurred:

Traceback (most recent call last):
  File "/root/Envs/haole-uumOUkom/lib/python3.6/site-packages/django/template/base.py", line 843, in _resolve_lookup
    current = current[int(bit)]
ValueError: invalid literal for int() with base 10: 'name'

During handling of the above exception, another exception occurred:

Traceback (most recent call last):
  File "/root/Envs/haole-uumOUkom/lib/python3.6/site-packages/django/template/base.py", line 850, in _resolve_lookup
    (bit, current))  # missing attribute
django.template.base.VariableDoesNotExist: Failed lookup for key [name] in <URLResolver <module 'apps.detail.urls' from './apps/detail/urls.py'> (None:None) 'article/'>
2020-06-21 08:27:06,840 [uWSGIWorker4Core0:139737293428224] [django.db.backends:110] [utils:execute] [DEBUG]- (0.000) SET SESSION TRANSACTION ISOLATION LEVEL READ COMMITTED; args=None
2020-06-21 08:27:06,840 [uWSGIWorker4Core0:139737293428224] [django.db.backends:110] [utils:execute] [DEBUG]- (0.000) SELECT `django_session`.`session_key`, `django_session`.`session_data`, `django_session`.`expire_date` FROM `django_session` WHERE (`django_session`.`expire_date` > '2020-06-21 08:27:06.838446' AND `django_session`.`session_key` = 'b9iwultyte977hm1pqjvmmpc03f8av7g'); args=('2020-06-21 08:27:06.838446', 'b9iwultyte977hm1pqjvmmpc03f8av7g')
2020-06-21 08:27:06,842 [uWSGIWorker4Core0:139737293428224] [django.db.backends:110] [utils:execute] [DEBUG]- (0.000) SELECT `auth_user`.`id`, `auth_user`.`password`, `auth_user`.`last_login`, `auth_user`.`is_superuser`, `auth_user`.`username`, `auth_user`.`first_name`, `auth_user`.`last_name`, `auth_user`.`email`, `auth_user`.`is_staff`, `auth_user`.`is_active`, `auth_user`.`date_joined` FROM `auth_user` WHERE `auth_user`.`id` = 1; args=(1,)
2020-06-21 08:27:06,845 [uWSGIWorker4Core0:139737293428224] [django.template:872] [base:_resolve_lookup] [DEBUG]- Exception while resolving variable 'name' in template 'unknown'.
Traceback (most recent call last):
  File "/root/Envs/haole-uumOUkom/lib/python3.6/site-packages/django/core/handlers/exception.py", line 34, in inner
    response = get_response(request)
  File "/root/Envs/haole-uumOUkom/lib/python3.6/site-packages/django/core/handlers/base.py", line 100, in _get_response
    resolver_match = resolver.resolve(request.path_info)
  File "/root/Envs/haole-uumOUkom/lib/python3.6/site-packages/django/urls/resolvers.py", line 558, in resolve
    raise Resolver404({'tried': tried, 'path': new_path})
django.urls.exceptions.Resolver404: {'tried': [[<URLResolver <URLPattern list> (admin:admin) 'admin/'>], [<URLResolver <module 'apps.home.urls' from './apps/home/urls.py'> (None:None) ''>, <URLPattern '' [name='home']>], [<URLResolver <module 'apps.home.urls' from './apps/home/urls.py'> (None:None) ''>, <URLPattern 'delete' [name='delete']>], [<URLResolver <module 'apps.detail.urls' from './apps/detail/urls.py'> (None:None) 'article/'>], [<URLPattern '^favicon.ico$'>]], 'path': 'template/default_pc/html/style/js/imagesloaded.pkgd.min.js'}

During handling of the above exception, another exception occurred:

Traceback (most recent call last):
  File "/root/Envs/haole-uumOUkom/lib/python3.6/site-packages/django/template/base.py", line 829, in _resolve_lookup
    current = current[bit]
TypeError: 'URLResolver' object is not subscriptable

During handling of the above exception, another exception occurred:

Traceback (most recent call last):
  File "/root/Envs/haole-uumOUkom/lib/python3.6/site-packages/django/template/base.py", line 837, in _resolve_lookup
    current = getattr(current, bit)
AttributeError: 'URLResolver' object has no attribute 'name'

During handling of the above exception, another exception occurred:

Traceback (most recent call last):
  File "/root/Envs/haole-uumOUkom/lib/python3.6/site-packages/django/template/base.py", line 843, in _resolve_lookup
    current = current[int(bit)]
ValueError: invalid literal for int() with base 10: 'name'

During handling of the above exception, another exception occurred:

Traceback (most recent call last):
  File "/root/Envs/haole-uumOUkom/lib/python3.6/site-packages/django/template/base.py", line 850, in _resolve_lookup
    (bit, current))  # missing attribute
django.template.base.VariableDoesNotExist: Failed lookup for key [name] in <URLResolver <URLPattern list> (admin:admin) 'admin/'>
2020-06-21 08:27:06,846 [uWSGIWorker4Core0:139737293428224] [django.template:872] [base:_resolve_lookup] [DEBUG]- Exception while resolving variable 'name' in template 'unknown'.
Traceback (most recent call last):
  File "/root/Envs/haole-uumOUkom/lib/python3.6/site-packages/django/core/handlers/exception.py", line 34, in inner
    response = get_response(request)
  File "/root/Envs/haole-uumOUkom/lib/python3.6/site-packages/django/core/handlers/base.py", line 100, in _get_response
    resolver_match = resolver.resolve(request.path_info)
  File "/root/Envs/haole-uumOUkom/lib/python3.6/site-packages/django/urls/resolvers.py", line 558, in resolve
    raise Resolver404({'tried': tried, 'path': new_path})
django.urls.exceptions.Resolver404: {'tried': [[<URLResolver <URLPattern list> (admin:admin) 'admin/'>], [<URLResolver <module 'apps.home.urls' from './apps/home/urls.py'> (None:None) ''>, <URLPattern '' [name='home']>], [<URLResolver <module 'apps.home.urls' from './apps/home/urls.py'> (None:None) ''>, <URLPattern 'delete' [name='delete']>], [<URLResolver <module 'apps.detail.urls' from './apps/detail/urls.py'> (None:None) 'article/'>], [<URLPattern '^favicon.ico$'>]], 'path': 'template/default_pc/html/style/js/imagesloaded.pkgd.min.js'}

During handling of the above exception, another exception occurred:

Traceback (most recent call last):
  File "/root/Envs/haole-uumOUkom/lib/python3.6/site-packages/django/template/base.py", line 829, in _resolve_lookup
    current = current[bit]
TypeError: 'URLResolver' object is not subscriptable

During handling of the above exception, another exception occurred:

Traceback (most recent call last):
  File "/root/Envs/haole-uumOUkom/lib/python3.6/site-packages/django/template/base.py", line 837, in _resolve_lookup
    current = getattr(current, bit)
AttributeError: 'URLResolver' object has no attribute 'name'

During handling of the above exception, another exception occurred:

Traceback (most recent call last):
  File "/root/Envs/haole-uumOUkom/lib/python3.6/site-packages/django/template/base.py", line 843, in _resolve_lookup
    current = current[int(bit)]
ValueError: invalid literal for int() with base 10: 'name'

During handling of the above exception, another exception occurred:

Traceback (most recent call last):
  File "/root/Envs/haole-uumOUkom/lib/python3.6/site-packages/django/template/base.py", line 850, in _resolve_lookup
    (bit, current))  # missing attribute
django.template.base.VariableDoesNotExist: Failed lookup for key [name] in <URLResolver <module 'apps.detail.urls' from './apps/detail/urls.py'> (None:None) 'article/'>
2020-06-21 08:27:14,550 [uWSGIWorker4Core0:139737293428224] [django.db.backends:110] [utils:execute] [DEBUG]- (0.000) SET SESSION TRANSACTION ISOLATION LEVEL READ COMMITTED; args=None
2020-06-21 08:27:14,550 [uWSGIWorker4Core0:139737293428224] [django.db.backends:110] [utils:execute] [DEBUG]- (0.000) SELECT `django_session`.`session_key`, `django_session`.`session_data`, `django_session`.`expire_date` FROM `django_session` WHERE (`django_session`.`expire_date` > '2020-06-21 08:27:14.548902' AND `django_session`.`session_key` = 'b9iwultyte977hm1pqjvmmpc03f8av7g'); args=('2020-06-21 08:27:14.548902', 'b9iwultyte977hm1pqjvmmpc03f8av7g')
2020-06-21 08:27:14,552 [uWSGIWorker4Core0:139737293428224] [django.db.backends:110] [utils:execute] [DEBUG]- (0.000) SELECT `auth_user`.`id`, `auth_user`.`password`, `auth_user`.`last_login`, `auth_user`.`is_superuser`, `auth_user`.`username`, `auth_user`.`first_name`, `auth_user`.`last_name`, `auth_user`.`email`, `auth_user`.`is_staff`, `auth_user`.`is_active`, `auth_user`.`date_joined` FROM `auth_user` WHERE `auth_user`.`id` = 1; args=(1,)
2020-06-21 08:27:14,577 [uWSGIWorker4Core0:139737293428224] [django.db.backends:110] [utils:execute] [DEBUG]- (0.024) SELECT `home_article`.`id`, `home_article`.`title`, `home_article`.`content_html`, `home_article`.`add_time`, `home_article`.`platform`, `home_article`.`platform_url`, `home_article`.`status` FROM `home_article` WHERE `home_article`.`id` = 1478; args=(1478,)
2020-06-21 08:27:14,701 [uWSGIWorker4Core0:139737293428224] [django.db.backends:110] [utils:execute] [DEBUG]- (0.000) SET SESSION TRANSACTION ISOLATION LEVEL READ COMMITTED; args=None
2020-06-21 08:27:14,702 [uWSGIWorker4Core0:139737293428224] [django.db.backends:110] [utils:execute] [DEBUG]- (0.000) SELECT `django_session`.`session_key`, `django_session`.`session_data`, `django_session`.`expire_date` FROM `django_session` WHERE (`django_session`.`expire_date` > '2020-06-21 08:27:14.698619' AND `django_session`.`session_key` = 'b9iwultyte977hm1pqjvmmpc03f8av7g'); args=('2020-06-21 08:27:14.698619', 'b9iwultyte977hm1pqjvmmpc03f8av7g')
2020-06-21 08:27:14,706 [uWSGIWorker4Core0:139737293428224] [django.db.backends:110] [utils:execute] [DEBUG]- (0.003) SELECT `auth_user`.`id`, `auth_user`.`password`, `auth_user`.`last_login`, `auth_user`.`is_superuser`, `auth_user`.`username`, `auth_user`.`first_name`, `auth_user`.`last_name`, `auth_user`.`email`, `auth_user`.`is_staff`, `auth_user`.`is_active`, `auth_user`.`date_joined` FROM `auth_user` WHERE `auth_user`.`id` = 1; args=(1,)
2020-06-21 08:27:14,714 [uWSGIWorker4Core0:139737293428224] [django.template:872] [base:_resolve_lookup] [DEBUG]- Exception while resolving variable 'name' in template 'unknown'.
Traceback (most recent call last):
  File "/root/Envs/haole-uumOUkom/lib/python3.6/site-packages/django/core/handlers/exception.py", line 34, in inner
    response = get_response(request)
  File "/root/Envs/haole-uumOUkom/lib/python3.6/site-packages/django/core/handlers/base.py", line 100, in _get_response
    resolver_match = resolver.resolve(request.path_info)
  File "/root/Envs/haole-uumOUkom/lib/python3.6/site-packages/django/urls/resolvers.py", line 558, in resolve
    raise Resolver404({'tried': tried, 'path': new_path})
django.urls.exceptions.Resolver404: {'tried': [[<URLResolver <URLPattern list> (admin:admin) 'admin/'>], [<URLResolver <module 'apps.home.urls' from './apps/home/urls.py'> (None:None) ''>, <URLPattern '' [name='home']>], [<URLResolver <module 'apps.home.urls' from './apps/home/urls.py'> (None:None) ''>, <URLPattern 'delete' [name='delete']>], [<URLResolver <module 'apps.detail.urls' from './apps/detail/urls.py'> (None:None) 'article/'>], [<URLPattern '^favicon.ico$'>]], 'path': 'template/default_pc/html/style/js/bootstrap.min.js'}

During handling of the above exception, another exception occurred:

Traceback (most recent call last):
  File "/root/Envs/haole-uumOUkom/lib/python3.6/site-packages/django/template/base.py", line 829, in _resolve_lookup
    current = current[bit]
TypeError: 'URLResolver' object is not subscriptable

During handling of the above exception, another exception occurred:

Traceback (most recent call last):
  File "/root/Envs/haole-uumOUkom/lib/python3.6/site-packages/django/template/base.py", line 837, in _resolve_lookup
    current = getattr(current, bit)
AttributeError: 'URLResolver' object has no attribute 'name'

During handling of the above exception, another exception occurred:

Traceback (most recent call last):
  File "/root/Envs/haole-uumOUkom/lib/python3.6/site-packages/django/template/base.py", line 843, in _resolve_lookup
    current = current[int(bit)]
ValueError: invalid literal for int() with base 10: 'name'

During handling of the above exception, another exception occurred:

Traceback (most recent call last):
  File "/root/Envs/haole-uumOUkom/lib/python3.6/site-packages/django/template/base.py", line 850, in _resolve_lookup
    (bit, current))  # missing attribute
django.template.base.VariableDoesNotExist: Failed lookup for key [name] in <URLResolver <URLPattern list> (admin:admin) 'admin/'>
2020-06-21 08:27:14,715 [uWSGIWorker4Core0:139737293428224] [django.template:872] [base:_resolve_lookup] [DEBUG]- Exception while resolving variable 'name' in template 'unknown'.
Traceback (most recent call last):
  File "/root/Envs/haole-uumOUkom/lib/python3.6/site-packages/django/core/handlers/exception.py", line 34, in inner
    response = get_response(request)
  File "/root/Envs/haole-uumOUkom/lib/python3.6/site-packages/django/core/handlers/base.py", line 100, in _get_response
    resolver_match = resolver.resolve(request.path_info)
  File "/root/Envs/haole-uumOUkom/lib/python3.6/site-packages/django/urls/resolvers.py", line 558, in resolve
    raise Resolver404({'tried': tried, 'path': new_path})
django.urls.exceptions.Resolver404: {'tried': [[<URLResolver <URLPattern list> (admin:admin) 'admin/'>], [<URLResolver <module 'apps.home.urls' from './apps/home/urls.py'> (None:None) ''>, <URLPattern '' [name='home']>], [<URLResolver <module 'apps.home.urls' from './apps/home/urls.py'> (None:None) ''>, <URLPattern 'delete' [name='delete']>], [<URLResolver <module 'apps.detail.urls' from './apps/detail/urls.py'> (None:None) 'article/'>], [<URLPattern '^favicon.ico$'>]], 'path': 'template/default_pc/html/style/js/bootstrap.min.js'}

During handling of the above exception, another exception occurred:

Traceback (most recent call last):
  File "/root/Envs/haole-uumOUkom/lib/python3.6/site-packages/django/template/base.py", line 829, in _resolve_lookup
    current = current[bit]
TypeError: 'URLResolver' object is not subscriptable

During handling of the above exception, another exception occurred:

Traceback (most recent call last):
  File "/root/Envs/haole-uumOUkom/lib/python3.6/site-packages/django/template/base.py", line 837, in _resolve_lookup
    current = getattr(current, bit)
AttributeError: 'URLResolver' object has no attribute 'name'

During handling of the above exception, another exception occurred:

Traceback (most recent call last):
  File "/root/Envs/haole-uumOUkom/lib/python3.6/site-packages/django/template/base.py", line 843, in _resolve_lookup
    current = current[int(bit)]
ValueError: invalid literal for int() with base 10: 'name'

During handling of the above exception, another exception occurred:

Traceback (most recent call last):
  File "/root/Envs/haole-uumOUkom/lib/python3.6/site-packages/django/template/base.py", line 850, in _resolve_lookup
    (bit, current))  # missing attribute
django.template.base.VariableDoesNotExist: Failed lookup for key [name] in <URLResolver <module 'apps.detail.urls' from './apps/detail/urls.py'> (None:None) 'article/'>
2020-06-21 08:27:14,777 [uWSGIWorker4Core0:139737293428224] [django.db.backends:110] [utils:execute] [DEBUG]- (0.001) SET SESSION TRANSACTION ISOLATION LEVEL READ COMMITTED; args=None
2020-06-21 08:27:14,778 [uWSGIWorker4Core0:139737293428224] [django.db.backends:110] [utils:execute] [DEBUG]- (0.000) SELECT `django_session`.`session_key`, `django_session`.`session_data`, `django_session`.`expire_date` FROM `django_session` WHERE (`django_session`.`expire_date` > '2020-06-21 08:27:14.769996' AND `django_session`.`session_key` = 'b9iwultyte977hm1pqjvmmpc03f8av7g'); args=('2020-06-21 08:27:14.769996', 'b9iwultyte977hm1pqjvmmpc03f8av7g')
2020-06-21 08:27:14,785 [uWSGIWorker4Core0:139737293428224] [django.db.backends:110] [utils:execute] [DEBUG]- (0.006) SELECT `auth_user`.`id`, `auth_user`.`password`, `auth_user`.`last_login`, `auth_user`.`is_superuser`, `auth_user`.`username`, `auth_user`.`first_name`, `auth_user`.`last_name`, `auth_user`.`email`, `auth_user`.`is_staff`, `auth_user`.`is_active`, `auth_user`.`date_joined` FROM `auth_user` WHERE `auth_user`.`id` = 1; args=(1,)
2020-06-21 08:27:14,788 [uWSGIWorker4Core0:139737293428224] [django.template:872] [base:_resolve_lookup] [DEBUG]- Exception while resolving variable 'name' in template 'unknown'.
Traceback (most recent call last):
  File "/root/Envs/haole-uumOUkom/lib/python3.6/site-packages/django/core/handlers/exception.py", line 34, in inner
    response = get_response(request)
  File "/root/Envs/haole-uumOUkom/lib/python3.6/site-packages/django/core/handlers/base.py", line 100, in _get_response
    resolver_match = resolver.resolve(request.path_info)
  File "/root/Envs/haole-uumOUkom/lib/python3.6/site-packages/django/urls/resolvers.py", line 558, in resolve
    raise Resolver404({'tried': tried, 'path': new_path})
django.urls.exceptions.Resolver404: {'tried': [[<URLResolver <URLPattern list> (admin:admin) 'admin/'>], [<URLResolver <module 'apps.home.urls' from './apps/home/urls.py'> (None:None) ''>, <URLPattern '' [name='home']>], [<URLResolver <module 'apps.home.urls' from './apps/home/urls.py'> (None:None) ''>, <URLPattern 'delete' [name='delete']>], [<URLResolver <module 'apps.detail.urls' from './apps/detail/urls.py'> (None:None) 'article/'>], [<URLPattern '^favicon.ico$'>]], 'path': 'template/default_pc/html/style/js/device.js'}

During handling of the above exception, another exception occurred:

Traceback (most recent call last):
  File "/root/Envs/haole-uumOUkom/lib/python3.6/site-packages/django/template/base.py", line 829, in _resolve_lookup
    current = current[bit]
TypeError: 'URLResolver' object is not subscriptable

During handling of the above exception, another exception occurred:

Traceback (most recent call last):
  File "/root/Envs/haole-uumOUkom/lib/python3.6/site-packages/django/template/base.py", line 837, in _resolve_lookup
    current = getattr(current, bit)
AttributeError: 'URLResolver' object has no attribute 'name'

During handling of the above exception, another exception occurred:

Traceback (most recent call last):
  File "/root/Envs/haole-uumOUkom/lib/python3.6/site-packages/django/template/base.py", line 843, in _resolve_lookup
    current = current[int(bit)]
ValueError: invalid literal for int() with base 10: 'name'

During handling of the above exception, another exception occurred:

Traceback (most recent call last):
  File "/root/Envs/haole-uumOUkom/lib/python3.6/site-packages/django/template/base.py", line 850, in _resolve_lookup
    (bit, current))  # missing attribute
django.template.base.VariableDoesNotExist: Failed lookup for key [name] in <URLResolver <URLPattern list> (admin:admin) 'admin/'>
2020-06-21 08:27:14,789 [uWSGIWorker4Core0:139737293428224] [django.template:872] [base:_resolve_lookup] [DEBUG]- Exception while resolving variable 'name' in template 'unknown'.
Traceback (most recent call last):
  File "/root/Envs/haole-uumOUkom/lib/python3.6/site-packages/django/core/handlers/exception.py", line 34, in inner
    response = get_response(request)
  File "/root/Envs/haole-uumOUkom/lib/python3.6/site-packages/django/core/handlers/base.py", line 100, in _get_response
    resolver_match = resolver.resolve(request.path_info)
  File "/root/Envs/haole-uumOUkom/lib/python3.6/site-packages/django/urls/resolvers.py", line 558, in resolve
    raise Resolver404({'tried': tried, 'path': new_path})
django.urls.exceptions.Resolver404: {'tried': [[<URLResolver <URLPattern list> (admin:admin) 'admin/'>], [<URLResolver <module 'apps.home.urls' from './apps/home/urls.py'> (None:None) ''>, <URLPattern '' [name='home']>], [<URLResolver <module 'apps.home.urls' from './apps/home/urls.py'> (None:None) ''>, <URLPattern 'delete' [name='delete']>], [<URLResolver <module 'apps.detail.urls' from './apps/detail/urls.py'> (None:None) 'article/'>], [<URLPattern '^favicon.ico$'>]], 'path': 'template/default_pc/html/style/js/device.js'}

During handling of the above exception, another exception occurred:

Traceback (most recent call last):
  File "/root/Envs/haole-uumOUkom/lib/python3.6/site-packages/django/template/base.py", line 829, in _resolve_lookup
    current = current[bit]
TypeError: 'URLResolver' object is not subscriptable

During handling of the above exception, another exception occurred:

Traceback (most recent call last):
  File "/root/Envs/haole-uumOUkom/lib/python3.6/site-packages/django/template/base.py", line 837, in _resolve_lookup
    current = getattr(current, bit)
AttributeError: 'URLResolver' object has no attribute 'name'

During handling of the above exception, another exception occurred:

Traceback (most recent call last):
  File "/root/Envs/haole-uumOUkom/lib/python3.6/site-packages/django/template/base.py", line 843, in _resolve_lookup
    current = current[int(bit)]
ValueError: invalid literal for int() with base 10: 'name'

During handling of the above exception, another exception occurred:

Traceback (most recent call last):
  File "/root/Envs/haole-uumOUkom/lib/python3.6/site-packages/django/template/base.py", line 850, in _resolve_lookup
    (bit, current))  # missing attribute
django.template.base.VariableDoesNotExist: Failed lookup for key [name] in <URLResolver <module 'apps.detail.urls' from './apps/detail/urls.py'> (None:None) 'article/'>
2020-06-21 08:27:15,003 [uWSGIWorker4Core0:139737293428224] [django.db.backends:110] [utils:execute] [DEBUG]- (0.000) SET SESSION TRANSACTION ISOLATION LEVEL READ COMMITTED; args=None
2020-06-21 08:27:15,004 [uWSGIWorker4Core0:139737293428224] [django.db.backends:110] [utils:execute] [DEBUG]- (0.000) SELECT `django_session`.`session_key`, `django_session`.`session_data`, `django_session`.`expire_date` FROM `django_session` WHERE (`django_session`.`expire_date` > '2020-06-21 08:27:15.002235' AND `django_session`.`session_key` = 'b9iwultyte977hm1pqjvmmpc03f8av7g'); args=('2020-06-21 08:27:15.002235', 'b9iwultyte977hm1pqjvmmpc03f8av7g')
2020-06-21 08:27:15,006 [uWSGIWorker4Core0:139737293428224] [django.db.backends:110] [utils:execute] [DEBUG]- (0.000) SELECT `auth_user`.`id`, `auth_user`.`password`, `auth_user`.`last_login`, `auth_user`.`is_superuser`, `auth_user`.`username`, `auth_user`.`first_name`, `auth_user`.`last_name`, `auth_user`.`email`, `auth_user`.`is_staff`, `auth_user`.`is_active`, `auth_user`.`date_joined` FROM `auth_user` WHERE `auth_user`.`id` = 1; args=(1,)
2020-06-21 08:27:15,009 [uWSGIWorker4Core0:139737293428224] [django.template:872] [base:_resolve_lookup] [DEBUG]- Exception while resolving variable 'name' in template 'unknown'.
Traceback (most recent call last):
  File "/root/Envs/haole-uumOUkom/lib/python3.6/site-packages/django/core/handlers/exception.py", line 34, in inner
    response = get_response(request)
  File "/root/Envs/haole-uumOUkom/lib/python3.6/site-packages/django/core/handlers/base.py", line 100, in _get_response
    resolver_match = resolver.resolve(request.path_info)
  File "/root/Envs/haole-uumOUkom/lib/python3.6/site-packages/django/urls/resolvers.py", line 558, in resolve
    raise Resolver404({'tried': tried, 'path': new_path})
django.urls.exceptions.Resolver404: {'tried': [[<URLResolver <URLPattern list> (admin:admin) 'admin/'>], [<URLResolver <module 'apps.home.urls' from './apps/home/urls.py'> (None:None) ''>, <URLPattern '' [name='home']>], [<URLResolver <module 'apps.home.urls' from './apps/home/urls.py'> (None:None) ''>, <URLPattern 'delete' [name='delete']>], [<URLResolver <module 'apps.detail.urls' from './apps/detail/urls.py'> (None:None) 'article/'>], [<URLPattern '^favicon.ico$'>]], 'path': 'template/default_pc/html/style/js/bootstrap.min.js'}

During handling of the above exception, another exception occurred:

Traceback (most recent call last):
  File "/root/Envs/haole-uumOUkom/lib/python3.6/site-packages/django/template/base.py", line 829, in _resolve_lookup
    current = current[bit]
TypeError: 'URLResolver' object is not subscriptable

During handling of the above exception, another exception occurred:

Traceback (most recent call last):
  File "/root/Envs/haole-uumOUkom/lib/python3.6/site-packages/django/template/base.py", line 837, in _resolve_lookup
    current = getattr(current, bit)
AttributeError: 'URLResolver' object has no attribute 'name'

During handling of the above exception, another exception occurred:

Traceback (most recent call last):
  File "/root/Envs/haole-uumOUkom/lib/python3.6/site-packages/django/template/base.py", line 843, in _resolve_lookup
    current = current[int(bit)]
ValueError: invalid literal for int() with base 10: 'name'

During handling of the above exception, another exception occurred:

Traceback (most recent call last):
  File "/root/Envs/haole-uumOUkom/lib/python3.6/site-packages/django/template/base.py", line 850, in _resolve_lookup
    (bit, current))  # missing attribute
django.template.base.VariableDoesNotExist: Failed lookup for key [name] in <URLResolver <URLPattern list> (admin:admin) 'admin/'>
2020-06-21 08:27:15,010 [uWSGIWorker4Core0:139737293428224] [django.template:872] [base:_resolve_lookup] [DEBUG]- Exception while resolving variable 'name' in template 'unknown'.
Traceback (most recent call last):
  File "/root/Envs/haole-uumOUkom/lib/python3.6/site-packages/django/core/handlers/exception.py", line 34, in inner
    response = get_response(request)
  File "/root/Envs/haole-uumOUkom/lib/python3.6/site-packages/django/core/handlers/base.py", line 100, in _get_response
    resolver_match = resolver.resolve(request.path_info)
  File "/root/Envs/haole-uumOUkom/lib/python3.6/site-packages/django/urls/resolvers.py", line 558, in resolve
    raise Resolver404({'tried': tried, 'path': new_path})
django.urls.exceptions.Resolver404: {'tried': [[<URLResolver <URLPattern list> (admin:admin) 'admin/'>], [<URLResolver <module 'apps.home.urls' from './apps/home/urls.py'> (None:None) ''>, <URLPattern '' [name='home']>], [<URLResolver <module 'apps.home.urls' from './apps/home/urls.py'> (None:None) ''>, <URLPattern 'delete' [name='delete']>], [<URLResolver <module 'apps.detail.urls' from './apps/detail/urls.py'> (None:None) 'article/'>], [<URLPattern '^favicon.ico$'>]], 'path': 'template/default_pc/html/style/js/bootstrap.min.js'}

During handling of the above exception, another exception occurred:

Traceback (most recent call last):
  File "/root/Envs/haole-uumOUkom/lib/python3.6/site-packages/django/template/base.py", line 829, in _resolve_lookup
    current = current[bit]
TypeError: 'URLResolver' object is not subscriptable

During handling of the above exception, another exception occurred:

Traceback (most recent call last):
  File "/root/Envs/haole-uumOUkom/lib/python3.6/site-packages/django/template/base.py", line 837, in _resolve_lookup
    current = getattr(current, bit)
AttributeError: 'URLResolver' object has no attribute 'name'

During handling of the above exception, another exception occurred:

Traceback (most recent call last):
  File "/root/Envs/haole-uumOUkom/lib/python3.6/site-packages/django/template/base.py", line 843, in _resolve_lookup
    current = current[int(bit)]
ValueError: invalid literal for int() with base 10: 'name'

During handling of the above exception, another exception occurred:

Traceback (most recent call last):
  File "/root/Envs/haole-uumOUkom/lib/python3.6/site-packages/django/template/base.py", line 850, in _resolve_lookup
    (bit, current))  # missing attribute
django.template.base.VariableDoesNotExist: Failed lookup for key [name] in <URLResolver <module 'apps.detail.urls' from './apps/detail/urls.py'> (None:None) 'article/'>
2020-06-21 08:27:15,181 [uWSGIWorker4Core0:139737293428224] [django.db.backends:110] [utils:execute] [DEBUG]- (0.000) SET SESSION TRANSACTION ISOLATION LEVEL READ COMMITTED; args=None
2020-06-21 08:27:15,182 [uWSGIWorker4Core0:139737293428224] [django.db.backends:110] [utils:execute] [DEBUG]- (0.000) SELECT `django_session`.`session_key`, `django_session`.`session_data`, `django_session`.`expire_date` FROM `django_session` WHERE (`django_session`.`expire_date` > '2020-06-21 08:27:15.180345' AND `django_session`.`session_key` = 'b9iwultyte977hm1pqjvmmpc03f8av7g'); args=('2020-06-21 08:27:15.180345', 'b9iwultyte977hm1pqjvmmpc03f8av7g')
2020-06-21 08:27:15,183 [uWSGIWorker4Core0:139737293428224] [django.db.backends:110] [utils:execute] [DEBUG]- (0.000) SELECT `auth_user`.`id`, `auth_user`.`password`, `auth_user`.`last_login`, `auth_user`.`is_superuser`, `auth_user`.`username`, `auth_user`.`first_name`, `auth_user`.`last_name`, `auth_user`.`email`, `auth_user`.`is_staff`, `auth_user`.`is_active`, `auth_user`.`date_joined` FROM `auth_user` WHERE `auth_user`.`id` = 1; args=(1,)
2020-06-21 08:27:15,185 [uWSGIWorker4Core0:139737293428224] [django.template:872] [base:_resolve_lookup] [DEBUG]- Exception while resolving variable 'name' in template 'unknown'.
Traceback (most recent call last):
  File "/root/Envs/haole-uumOUkom/lib/python3.6/site-packages/django/core/handlers/exception.py", line 34, in inner
    response = get_response(request)
  File "/root/Envs/haole-uumOUkom/lib/python3.6/site-packages/django/core/handlers/base.py", line 100, in _get_response
    resolver_match = resolver.resolve(request.path_info)
  File "/root/Envs/haole-uumOUkom/lib/python3.6/site-packages/django/urls/resolvers.py", line 558, in resolve
    raise Resolver404({'tried': tried, 'path': new_path})
django.urls.exceptions.Resolver404: {'tried': [[<URLResolver <URLPattern list> (admin:admin) 'admin/'>], [<URLResolver <module 'apps.home.urls' from './apps/home/urls.py'> (None:None) ''>, <URLPattern '' [name='home']>], [<URLResolver <module 'apps.home.urls' from './apps/home/urls.py'> (None:None) ''>, <URLPattern 'delete' [name='delete']>], [<URLResolver <module 'apps.detail.urls' from './apps/detail/urls.py'> (None:None) 'article/'>], [<URLPattern '^favicon.ico$'>]], 'path': 'template/default_pc/html/style/js/lazyload.min.js'}

During handling of the above exception, another exception occurred:

Traceback (most recent call last):
  File "/root/Envs/haole-uumOUkom/lib/python3.6/site-packages/django/template/base.py", line 829, in _resolve_lookup
    current = current[bit]
TypeError: 'URLResolver' object is not subscriptable

During handling of the above exception, another exception occurred:

Traceback (most recent call last):
  File "/root/Envs/haole-uumOUkom/lib/python3.6/site-packages/django/template/base.py", line 837, in _resolve_lookup
    current = getattr(current, bit)
AttributeError: 'URLResolver' object has no attribute 'name'

During handling of the above exception, another exception occurred:

Traceback (most recent call last):
  File "/root/Envs/haole-uumOUkom/lib/python3.6/site-packages/django/template/base.py", line 843, in _resolve_lookup
    current = current[int(bit)]
ValueError: invalid literal for int() with base 10: 'name'

During handling of the above exception, another exception occurred:

Traceback (most recent call last):
  File "/root/Envs/haole-uumOUkom/lib/python3.6/site-packages/django/template/base.py", line 850, in _resolve_lookup
    (bit, current))  # missing attribute
django.template.base.VariableDoesNotExist: Failed lookup for key [name] in <URLResolver <URLPattern list> (admin:admin) 'admin/'>
2020-06-21 08:27:15,186 [uWSGIWorker4Core0:139737293428224] [django.template:872] [base:_resolve_lookup] [DEBUG]- Exception while resolving variable 'name' in template 'unknown'.
Traceback (most recent call last):
  File "/root/Envs/haole-uumOUkom/lib/python3.6/site-packages/django/core/handlers/exception.py", line 34, in inner
    response = get_response(request)
  File "/root/Envs/haole-uumOUkom/lib/python3.6/site-packages/django/core/handlers/base.py", line 100, in _get_response
    resolver_match = resolver.resolve(request.path_info)
  File "/root/Envs/haole-uumOUkom/lib/python3.6/site-packages/django/urls/resolvers.py", line 558, in resolve
    raise Resolver404({'tried': tried, 'path': new_path})
django.urls.exceptions.Resolver404: {'tried': [[<URLResolver <URLPattern list> (admin:admin) 'admin/'>], [<URLResolver <module 'apps.home.urls' from './apps/home/urls.py'> (None:None) ''>, <URLPattern '' [name='home']>], [<URLResolver <module 'apps.home.urls' from './apps/home/urls.py'> (None:None) ''>, <URLPattern 'delete' [name='delete']>], [<URLResolver <module 'apps.detail.urls' from './apps/detail/urls.py'> (None:None) 'article/'>], [<URLPattern '^favicon.ico$'>]], 'path': 'template/default_pc/html/style/js/lazyload.min.js'}

During handling of the above exception, another exception occurred:

Traceback (most recent call last):
  File "/root/Envs/haole-uumOUkom/lib/python3.6/site-packages/django/template/base.py", line 829, in _resolve_lookup
    current = current[bit]
TypeError: 'URLResolver' object is not subscriptable

During handling of the above exception, another exception occurred:

Traceback (most recent call last):
  File "/root/Envs/haole-uumOUkom/lib/python3.6/site-packages/django/template/base.py", line 837, in _resolve_lookup
    current = getattr(current, bit)
AttributeError: 'URLResolver' object has no attribute 'name'

During handling of the above exception, another exception occurred:

Traceback (most recent call last):
  File "/root/Envs/haole-uumOUkom/lib/python3.6/site-packages/django/template/base.py", line 843, in _resolve_lookup
    current = current[int(bit)]
ValueError: invalid literal for int() with base 10: 'name'

During handling of the above exception, another exception occurred:

Traceback (most recent call last):
  File "/root/Envs/haole-uumOUkom/lib/python3.6/site-packages/django/template/base.py", line 850, in _resolve_lookup
    (bit, current))  # missing attribute
django.template.base.VariableDoesNotExist: Failed lookup for key [name] in <URLResolver <module 'apps.detail.urls' from './apps/detail/urls.py'> (None:None) 'article/'>
2020-06-21 08:27:15,347 [uWSGIWorker4Core0:139737293428224] [django.db.backends:110] [utils:execute] [DEBUG]- (0.000) SET SESSION TRANSACTION ISOLATION LEVEL READ COMMITTED; args=None
2020-06-21 08:27:15,347 [uWSGIWorker4Core0:139737293428224] [django.db.backends:110] [utils:execute] [DEBUG]- (0.000) SELECT `django_session`.`session_key`, `django_session`.`session_data`, `django_session`.`expire_date` FROM `django_session` WHERE (`django_session`.`expire_date` > '2020-06-21 08:27:15.346150' AND `django_session`.`session_key` = 'b9iwultyte977hm1pqjvmmpc03f8av7g'); args=('2020-06-21 08:27:15.346150', 'b9iwultyte977hm1pqjvmmpc03f8av7g')
2020-06-21 08:27:15,349 [uWSGIWorker4Core0:139737293428224] [django.db.backends:110] [utils:execute] [DEBUG]- (0.000) SELECT `auth_user`.`id`, `auth_user`.`password`, `auth_user`.`last_login`, `auth_user`.`is_superuser`, `auth_user`.`username`, `auth_user`.`first_name`, `auth_user`.`last_name`, `auth_user`.`email`, `auth_user`.`is_staff`, `auth_user`.`is_active`, `auth_user`.`date_joined` FROM `auth_user` WHERE `auth_user`.`id` = 1; args=(1,)
2020-06-21 08:27:15,351 [uWSGIWorker4Core0:139737293428224] [django.template:872] [base:_resolve_lookup] [DEBUG]- Exception while resolving variable 'name' in template 'unknown'.
Traceback (most recent call last):
  File "/root/Envs/haole-uumOUkom/lib/python3.6/site-packages/django/core/handlers/exception.py", line 34, in inner
    response = get_response(request)
  File "/root/Envs/haole-uumOUkom/lib/python3.6/site-packages/django/core/handlers/base.py", line 100, in _get_response
    resolver_match = resolver.resolve(request.path_info)
  File "/root/Envs/haole-uumOUkom/lib/python3.6/site-packages/django/urls/resolvers.py", line 558, in resolve
    raise Resolver404({'tried': tried, 'path': new_path})
django.urls.exceptions.Resolver404: {'tried': [[<URLResolver <URLPattern list> (admin:admin) 'admin/'>], [<URLResolver <module 'apps.home.urls' from './apps/home/urls.py'> (None:None) ''>, <URLPattern '' [name='home']>], [<URLResolver <module 'apps.home.urls' from './apps/home/urls.py'> (None:None) ''>, <URLPattern 'delete' [name='delete']>], [<URLResolver <module 'apps.detail.urls' from './apps/detail/urls.py'> (None:None) 'article/'>], [<URLPattern '^favicon.ico$'>]], 'path': 'template/default_pc/html/style/js/masonry.pkgd.min.js'}

During handling of the above exception, another exception occurred:

Traceback (most recent call last):
  File "/root/Envs/haole-uumOUkom/lib/python3.6/site-packages/django/template/base.py", line 829, in _resolve_lookup
    current = current[bit]
TypeError: 'URLResolver' object is not subscriptable

During handling of the above exception, another exception occurred:

Traceback (most recent call last):
  File "/root/Envs/haole-uumOUkom/lib/python3.6/site-packages/django/template/base.py", line 837, in _resolve_lookup
    current = getattr(current, bit)
AttributeError: 'URLResolver' object has no attribute 'name'

During handling of the above exception, another exception occurred:

Traceback (most recent call last):
  File "/root/Envs/haole-uumOUkom/lib/python3.6/site-packages/django/template/base.py", line 843, in _resolve_lookup
    current = current[int(bit)]
ValueError: invalid literal for int() with base 10: 'name'

During handling of the above exception, another exception occurred:

Traceback (most recent call last):
  File "/root/Envs/haole-uumOUkom/lib/python3.6/site-packages/django/template/base.py", line 850, in _resolve_lookup
    (bit, current))  # missing attribute
django.template.base.VariableDoesNotExist: Failed lookup for key [name] in <URLResolver <URLPattern list> (admin:admin) 'admin/'>
2020-06-21 08:27:15,352 [uWSGIWorker4Core0:139737293428224] [django.template:872] [base:_resolve_lookup] [DEBUG]- Exception while resolving variable 'name' in template 'unknown'.
Traceback (most recent call last):
  File "/root/Envs/haole-uumOUkom/lib/python3.6/site-packages/django/core/handlers/exception.py", line 34, in inner
    response = get_response(request)
  File "/root/Envs/haole-uumOUkom/lib/python3.6/site-packages/django/core/handlers/base.py", line 100, in _get_response
    resolver_match = resolver.resolve(request.path_info)
  File "/root/Envs/haole-uumOUkom/lib/python3.6/site-packages/django/urls/resolvers.py", line 558, in resolve
    raise Resolver404({'tried': tried, 'path': new_path})
django.urls.exceptions.Resolver404: {'tried': [[<URLResolver <URLPattern list> (admin:admin) 'admin/'>], [<URLResolver <module 'apps.home.urls' from './apps/home/urls.py'> (None:None) ''>, <URLPattern '' [name='home']>], [<URLResolver <module 'apps.home.urls' from './apps/home/urls.py'> (None:None) ''>, <URLPattern 'delete' [name='delete']>], [<URLResolver <module 'apps.detail.urls' from './apps/detail/urls.py'> (None:None) 'article/'>], [<URLPattern '^favicon.ico$'>]], 'path': 'template/default_pc/html/style/js/masonry.pkgd.min.js'}

During handling of the above exception, another exception occurred:

Traceback (most recent call last):
  File "/root/Envs/haole-uumOUkom/lib/python3.6/site-packages/django/template/base.py", line 829, in _resolve_lookup
    current = current[bit]
TypeError: 'URLResolver' object is not subscriptable

During handling of the above exception, another exception occurred:

Traceback (most recent call last):
  File "/root/Envs/haole-uumOUkom/lib/python3.6/site-packages/django/template/base.py", line 837, in _resolve_lookup
    current = getattr(current, bit)
AttributeError: 'URLResolver' object has no attribute 'name'

During handling of the above exception, another exception occurred:

Traceback (most recent call last):
  File "/root/Envs/haole-uumOUkom/lib/python3.6/site-packages/django/template/base.py", line 843, in _resolve_lookup
    current = current[int(bit)]
ValueError: invalid literal for int() with base 10: 'name'

During handling of the above exception, another exception occurred:

Traceback (most recent call last):
  File "/root/Envs/haole-uumOUkom/lib/python3.6/site-packages/django/template/base.py", line 850, in _resolve_lookup
    (bit, current))  # missing attribute
django.template.base.VariableDoesNotExist: Failed lookup for key [name] in <URLResolver <module 'apps.detail.urls' from './apps/detail/urls.py'> (None:None) 'article/'>
2020-06-21 08:27:23,706 [uWSGIWorker4Core0:139737293428224] [django.db.backends:110] [utils:execute] [DEBUG]- (0.000) SET SESSION TRANSACTION ISOLATION LEVEL READ COMMITTED; args=None
2020-06-21 08:27:23,709 [uWSGIWorker4Core0:139737293428224] [django.db.backends:110] [utils:execute] [DEBUG]- (0.000) SELECT `django_session`.`session_key`, `django_session`.`session_data`, `django_session`.`expire_date` FROM `django_session` WHERE (`django_session`.`expire_date` > '2020-06-21 08:27:23.704506' AND `django_session`.`session_key` = 'b9iwultyte977hm1pqjvmmpc03f8av7g'); args=('2020-06-21 08:27:23.704506', 'b9iwultyte977hm1pqjvmmpc03f8av7g')
2020-06-21 08:27:23,711 [uWSGIWorker4Core0:139737293428224] [django.db.backends:110] [utils:execute] [DEBUG]- (0.000) SELECT `auth_user`.`id`, `auth_user`.`password`, `auth_user`.`last_login`, `auth_user`.`is_superuser`, `auth_user`.`username`, `auth_user`.`first_name`, `auth_user`.`last_name`, `auth_user`.`email`, `auth_user`.`is_staff`, `auth_user`.`is_active`, `auth_user`.`date_joined` FROM `auth_user` WHERE `auth_user`.`id` = 1; args=(1,)
2020-06-21 08:27:38,166 [uWSGIWorker4Core0:139737293428224] [django.db.backends:110] [utils:execute] [DEBUG]- (0.000) SET SESSION TRANSACTION ISOLATION LEVEL READ COMMITTED; args=None
2020-06-21 08:27:38,166 [uWSGIWorker4Core0:139737293428224] [django.db.backends:110] [utils:execute] [DEBUG]- (0.000) SELECT `django_session`.`session_key`, `django_session`.`session_data`, `django_session`.`expire_date` FROM `django_session` WHERE (`django_session`.`expire_date` > '2020-06-21 08:27:38.164898' AND `django_session`.`session_key` = 'b9iwultyte977hm1pqjvmmpc03f8av7g'); args=('2020-06-21 08:27:38.164898', 'b9iwultyte977hm1pqjvmmpc03f8av7g')
2020-06-21 08:27:38,168 [uWSGIWorker4Core0:139737293428224] [django.db.backends:110] [utils:execute] [DEBUG]- (0.000) SELECT `auth_user`.`id`, `auth_user`.`password`, `auth_user`.`last_login`, `auth_user`.`is_superuser`, `auth_user`.`username`, `auth_user`.`first_name`, `auth_user`.`last_name`, `auth_user`.`email`, `auth_user`.`is_staff`, `auth_user`.`is_active`, `auth_user`.`date_joined` FROM `auth_user` WHERE `auth_user`.`id` = 1; args=(1,)
2020-06-21 08:27:53,918 [uWSGIWorker4Core0:139737293428224] [django.db.backends:110] [utils:execute] [DEBUG]- (0.000) SET SESSION TRANSACTION ISOLATION LEVEL READ COMMITTED; args=None
2020-06-21 08:27:53,919 [uWSGIWorker4Core0:139737293428224] [django.db.backends:110] [utils:execute] [DEBUG]- (0.000) SELECT `django_session`.`session_key`, `django_session`.`session_data`, `django_session`.`expire_date` FROM `django_session` WHERE (`django_session`.`expire_date` > '2020-06-21 08:27:53.917752' AND `django_session`.`session_key` = 'b9iwultyte977hm1pqjvmmpc03f8av7g'); args=('2020-06-21 08:27:53.917752', 'b9iwultyte977hm1pqjvmmpc03f8av7g')
2020-06-21 08:27:53,920 [uWSGIWorker4Core0:139737293428224] [django.db.backends:110] [utils:execute] [DEBUG]- (0.000) SELECT `auth_user`.`id`, `auth_user`.`password`, `auth_user`.`last_login`, `auth_user`.`is_superuser`, `auth_user`.`username`, `auth_user`.`first_name`, `auth_user`.`last_name`, `auth_user`.`email`, `auth_user`.`is_staff`, `auth_user`.`is_active`, `auth_user`.`date_joined` FROM `auth_user` WHERE `auth_user`.`id` = 1; args=(1,)
2020-06-21 08:28:03,076 [uWSGIWorker4Core0:139737293428224] [django.db.backends:110] [utils:execute] [DEBUG]- (0.000) SET SESSION TRANSACTION ISOLATION LEVEL READ COMMITTED; args=None
2020-06-21 08:28:03,076 [uWSGIWorker4Core0:139737293428224] [django.db.backends:110] [utils:execute] [DEBUG]- (0.000) SELECT `django_session`.`session_key`, `django_session`.`session_data`, `django_session`.`expire_date` FROM `django_session` WHERE (`django_session`.`expire_date` > '2020-06-21 08:28:03.075067' AND `django_session`.`session_key` = 'b9iwultyte977hm1pqjvmmpc03f8av7g'); args=('2020-06-21 08:28:03.075067', 'b9iwultyte977hm1pqjvmmpc03f8av7g')
2020-06-21 08:28:03,078 [uWSGIWorker4Core0:139737293428224] [django.db.backends:110] [utils:execute] [DEBUG]- (0.000) SELECT `auth_user`.`id`, `auth_user`.`password`, `auth_user`.`last_login`, `auth_user`.`is_superuser`, `auth_user`.`username`, `auth_user`.`first_name`, `auth_user`.`last_name`, `auth_user`.`email`, `auth_user`.`is_staff`, `auth_user`.`is_active`, `auth_user`.`date_joined` FROM `auth_user` WHERE `auth_user`.`id` = 1; args=(1,)
2020-06-21 08:28:18,377 [uWSGIWorker4Core0:139737293428224] [django.db.backends:110] [utils:execute] [DEBUG]- (0.000) SET SESSION TRANSACTION ISOLATION LEVEL READ COMMITTED; args=None
2020-06-21 08:28:18,377 [uWSGIWorker4Core0:139737293428224] [django.db.backends:110] [utils:execute] [DEBUG]- (0.000) SELECT `django_session`.`session_key`, `django_session`.`session_data`, `django_session`.`expire_date` FROM `django_session` WHERE (`django_session`.`expire_date` > '2020-06-21 08:28:18.375998' AND `django_session`.`session_key` = 'b9iwultyte977hm1pqjvmmpc03f8av7g'); args=('2020-06-21 08:28:18.375998', 'b9iwultyte977hm1pqjvmmpc03f8av7g')
2020-06-21 08:28:18,379 [uWSGIWorker4Core0:139737293428224] [django.db.backends:110] [utils:execute] [DEBUG]- (0.000) SELECT `auth_user`.`id`, `auth_user`.`password`, `auth_user`.`last_login`, `auth_user`.`is_superuser`, `auth_user`.`username`, `auth_user`.`first_name`, `auth_user`.`last_name`, `auth_user`.`email`, `auth_user`.`is_staff`, `auth_user`.`is_active`, `auth_user`.`date_joined` FROM `auth_user` WHERE `auth_user`.`id` = 1; args=(1,)
2020-06-21 08:28:18,401 [uWSGIWorker4Core0:139737293428224] [django.db.backends:110] [utils:execute] [DEBUG]- (0.021) SELECT `home_article`.`id`, `home_article`.`title`, `home_article`.`content_html`, `home_article`.`add_time`, `home_article`.`platform`, `home_article`.`platform_url`, `home_article`.`status` FROM `home_article` WHERE `home_article`.`id` = 15183; args=(15183,)
2020-06-21 08:28:40,073 [uWSGIWorker4Core0:139737293428224] [django.db.backends:110] [utils:execute] [DEBUG]- (0.000) SET SESSION TRANSACTION ISOLATION LEVEL READ COMMITTED; args=None
2020-06-21 08:28:40,073 [uWSGIWorker4Core0:139737293428224] [django.db.backends:110] [utils:execute] [DEBUG]- (0.000) SELECT `django_session`.`session_key`, `django_session`.`session_data`, `django_session`.`expire_date` FROM `django_session` WHERE (`django_session`.`expire_date` > '2020-06-21 08:28:40.071730' AND `django_session`.`session_key` = 'b9iwultyte977hm1pqjvmmpc03f8av7g'); args=('2020-06-21 08:28:40.071730', 'b9iwultyte977hm1pqjvmmpc03f8av7g')
2020-06-21 08:28:40,075 [uWSGIWorker4Core0:139737293428224] [django.db.backends:110] [utils:execute] [DEBUG]- (0.000) SELECT `auth_user`.`id`, `auth_user`.`password`, `auth_user`.`last_login`, `auth_user`.`is_superuser`, `auth_user`.`username`, `auth_user`.`first_name`, `auth_user`.`last_name`, `auth_user`.`email`, `auth_user`.`is_staff`, `auth_user`.`is_active`, `auth_user`.`date_joined` FROM `auth_user` WHERE `auth_user`.`id` = 1; args=(1,)
2020-06-21 08:28:58,705 [uWSGIWorker4Core0:139737293428224] [django.db.backends:110] [utils:execute] [DEBUG]- (0.000) SET SESSION TRANSACTION ISOLATION LEVEL READ COMMITTED; args=None
2020-06-21 08:28:58,706 [uWSGIWorker4Core0:139737293428224] [django.db.backends:110] [utils:execute] [DEBUG]- (0.000) SELECT `django_session`.`session_key`, `django_session`.`session_data`, `django_session`.`expire_date` FROM `django_session` WHERE (`django_session`.`expire_date` > '2020-06-21 08:28:58.704194' AND `django_session`.`session_key` = 'b9iwultyte977hm1pqjvmmpc03f8av7g'); args=('2020-06-21 08:28:58.704194', 'b9iwultyte977hm1pqjvmmpc03f8av7g')
2020-06-21 08:28:58,707 [uWSGIWorker4Core0:139737293428224] [django.db.backends:110] [utils:execute] [DEBUG]- (0.000) SELECT `auth_user`.`id`, `auth_user`.`password`, `auth_user`.`last_login`, `auth_user`.`is_superuser`, `auth_user`.`username`, `auth_user`.`first_name`, `auth_user`.`last_name`, `auth_user`.`email`, `auth_user`.`is_staff`, `auth_user`.`is_active`, `auth_user`.`date_joined` FROM `auth_user` WHERE `auth_user`.`id` = 1; args=(1,)
2020-06-21 08:29:10,221 [uWSGIWorker4Core0:139737293428224] [django.db.backends:110] [utils:execute] [DEBUG]- (0.000) SET SESSION TRANSACTION ISOLATION LEVEL READ COMMITTED; args=None
2020-06-21 08:29:10,222 [uWSGIWorker4Core0:139737293428224] [django.db.backends:110] [utils:execute] [DEBUG]- (0.000) SELECT `django_session`.`session_key`, `django_session`.`session_data`, `django_session`.`expire_date` FROM `django_session` WHERE (`django_session`.`expire_date` > '2020-06-21 08:29:10.220446' AND `django_session`.`session_key` = 'b9iwultyte977hm1pqjvmmpc03f8av7g'); args=('2020-06-21 08:29:10.220446', 'b9iwultyte977hm1pqjvmmpc03f8av7g')
2020-06-21 08:29:10,223 [uWSGIWorker4Core0:139737293428224] [django.db.backends:110] [utils:execute] [DEBUG]- (0.000) SELECT `auth_user`.`id`, `auth_user`.`password`, `auth_user`.`last_login`, `auth_user`.`is_superuser`, `auth_user`.`username`, `auth_user`.`first_name`, `auth_user`.`last_name`, `auth_user`.`email`, `auth_user`.`is_staff`, `auth_user`.`is_active`, `auth_user`.`date_joined` FROM `auth_user` WHERE `auth_user`.`id` = 1; args=(1,)
2020-06-21 08:29:19,183 [uWSGIWorker4Core0:139737293428224] [django.db.backends:110] [utils:execute] [DEBUG]- (0.000) SET SESSION TRANSACTION ISOLATION LEVEL READ COMMITTED; args=None
2020-06-21 08:29:19,186 [uWSGIWorker4Core0:139737293428224] [django.db.backends:110] [utils:execute] [DEBUG]- (0.000) SELECT `django_session`.`session_key`, `django_session`.`session_data`, `django_session`.`expire_date` FROM `django_session` WHERE (`django_session`.`expire_date` > '2020-06-21 08:29:19.181905' AND `django_session`.`session_key` = 'b9iwultyte977hm1pqjvmmpc03f8av7g'); args=('2020-06-21 08:29:19.181905', 'b9iwultyte977hm1pqjvmmpc03f8av7g')
2020-06-21 08:29:19,187 [uWSGIWorker4Core0:139737293428224] [django.db.backends:110] [utils:execute] [DEBUG]- (0.000) SELECT `auth_user`.`id`, `auth_user`.`password`, `auth_user`.`last_login`, `auth_user`.`is_superuser`, `auth_user`.`username`, `auth_user`.`first_name`, `auth_user`.`last_name`, `auth_user`.`email`, `auth_user`.`is_staff`, `auth_user`.`is_active`, `auth_user`.`date_joined` FROM `auth_user` WHERE `auth_user`.`id` = 1; args=(1,)
2020-06-21 08:29:24,534 [uWSGIWorker4Core0:139737293428224] [django.db.backends:110] [utils:execute] [DEBUG]- (0.000) SET SESSION TRANSACTION ISOLATION LEVEL READ COMMITTED; args=None
2020-06-21 08:29:24,537 [uWSGIWorker4Core0:139737293428224] [django.db.backends:110] [utils:execute] [DEBUG]- (0.000) SELECT `django_session`.`session_key`, `django_session`.`session_data`, `django_session`.`expire_date` FROM `django_session` WHERE (`django_session`.`expire_date` > '2020-06-21 08:29:24.533624' AND `django_session`.`session_key` = 'b9iwultyte977hm1pqjvmmpc03f8av7g'); args=('2020-06-21 08:29:24.533624', 'b9iwultyte977hm1pqjvmmpc03f8av7g')
2020-06-21 08:29:24,538 [uWSGIWorker4Core0:139737293428224] [django.db.backends:110] [utils:execute] [DEBUG]- (0.000) SELECT `auth_user`.`id`, `auth_user`.`password`, `auth_user`.`last_login`, `auth_user`.`is_superuser`, `auth_user`.`username`, `auth_user`.`first_name`, `auth_user`.`last_name`, `auth_user`.`email`, `auth_user`.`is_staff`, `auth_user`.`is_active`, `auth_user`.`date_joined` FROM `auth_user` WHERE `auth_user`.`id` = 1; args=(1,)
