2020-06-21 08:27:06,312 [uWSGIWorker3Core0:139737293428224] [django.template:872] [base:_resolve_lookup] [DEBUG]- Exception while resolving variable 'name' in template 'unknown'.
Traceback (most recent call last):
  File "/root/Envs/haole-uumOUkom/lib/python3.6/site-packages/django/core/handlers/exception.py", line 34, in inner
    response = get_response(request)
  File "/root/Envs/haole-uumOUkom/lib/python3.6/site-packages/django/core/handlers/base.py", line 100, in _get_response
    resolver_match = resolver.resolve(request.path_info)
  File "/root/Envs/haole-uumOUkom/lib/python3.6/site-packages/django/urls/resolvers.py", line 558, in resolve
    raise Resolver404({'tried': tried, 'path': new_path})
django.urls.exceptions.Resolver404: {'tried': [[<URLResolver <URLPattern list> (admin:admin) 'admin/'>], [<URLResolver <module 'apps.home.urls' from './apps/home/urls.py'> (None:None) ''>, <URLPattern '' [name='home']>], [<URLResolver <module 'apps.home.urls' from './apps/home/urls.py'> (None:None) ''>, <URLPattern 'delete' [name='delete']>], [<URLResolver <module 'apps.detail.urls' from './apps/detail/urls.py'> (None:None) 'article/'>], [<URLPattern '^favicon.ico$'>]], 'path': 'template/default_pc/html/style/js/device.js'}

During handling of the above exception, another exception occurred:

Traceback (most recent call last):
  File "/root/Envs/haole-uumOUkom/lib/python3.6/site-packages/django/template/base.py", line 829, in _resolve_lookup
    current = current[bit]
TypeError: 'URLResolver' object is not subscriptable

During handling of the above exception, another exception occurred:

Traceback (most recent call last):
  File "/root/Envs/haole-uumOUkom/lib/python3.6/site-packages/django/template/base.py", line 837, in _resolve_lookup
    current = getattr(current, bit)
AttributeError: 'URLResolver' object has no attribute 'name'

During handling of the above exception, another exception occurred:

Traceback (most recent call last):
  File "/root/Envs/haole-uumOUkom/lib/python3.6/site-packages/django/template/base.py", line 843, in _resolve_lookup
    current = current[int(bit)]
ValueError: invalid literal for int() with base 10: 'name'

During handling of the above exception, another exception occurred:

Traceback (most recent call last):
  File "/root/Envs/haole-uumOUkom/lib/python3.6/site-packages/django/template/base.py", line 850, in _resolve_lookup
    (bit, current))  # missing attribute
django.template.base.VariableDoesNotExist: Failed lookup for key [name] in <URLResolver <URLPattern list> (admin:admin) 'admin/'>
2020-06-21 08:27:06,321 [uWSGIWorker3Core0:139737293428224] [django.template:872] [base:_resolve_lookup] [DEBUG]- Exception while resolving variable 'name' in template 'unknown'.
Traceback (most recent call last):
  File "/root/Envs/haole-uumOUkom/lib/python3.6/site-packages/django/core/handlers/exception.py", line 34, in inner
    response = get_response(request)
  File "/root/Envs/haole-uumOUkom/lib/python3.6/site-packages/django/core/handlers/base.py", line 100, in _get_response
    resolver_match = resolver.resolve(request.path_info)
  File "/root/Envs/haole-uumOUkom/lib/python3.6/site-packages/django/urls/resolvers.py", line 558, in resolve
    raise Resolver404({'tried': tried, 'path': new_path})
django.urls.exceptions.Resolver404: {'tried': [[<URLResolver <URLPattern list> (admin:admin) 'admin/'>], [<URLResolver <module 'apps.home.urls' from './apps/home/urls.py'> (None:None) ''>, <URLPattern '' [name='home']>], [<URLResolver <module 'apps.home.urls' from './apps/home/urls.py'> (None:None) ''>, <URLPattern 'delete' [name='delete']>], [<URLResolver <module 'apps.detail.urls' from './apps/detail/urls.py'> (None:None) 'article/'>], [<URLPattern '^favicon.ico$'>]], 'path': 'template/default_pc/html/style/js/device.js'}

During handling of the above exception, another exception occurred:

Traceback (most recent call last):
  File "/root/Envs/haole-uumOUkom/lib/python3.6/site-packages/django/template/base.py", line 829, in _resolve_lookup
    current = current[bit]
TypeError: 'URLResolver' object is not subscriptable

During handling of the above exception, another exception occurred:

Traceback (most recent call last):
  File "/root/Envs/haole-uumOUkom/lib/python3.6/site-packages/django/template/base.py", line 837, in _resolve_lookup
    current = getattr(current, bit)
AttributeError: 'URLResolver' object has no attribute 'name'

During handling of the above exception, another exception occurred:

Traceback (most recent call last):
  File "/root/Envs/haole-uumOUkom/lib/python3.6/site-packages/django/template/base.py", line 843, in _resolve_lookup
    current = current[int(bit)]
ValueError: invalid literal for int() with base 10: 'name'

During handling of the above exception, another exception occurred:

Traceback (most recent call last):
  File "/root/Envs/haole-uumOUkom/lib/python3.6/site-packages/django/template/base.py", line 850, in _resolve_lookup
    (bit, current))  # missing attribute
django.template.base.VariableDoesNotExist: Failed lookup for key [name] in <URLResolver <module 'apps.detail.urls' from './apps/detail/urls.py'> (None:None) 'article/'>
2020-06-21 08:27:14,684 [uWSGIWorker3Core0:139737293428224] [django.db.backends:110] [utils:execute] [DEBUG]- (0.000) SET SESSION TRANSACTION ISOLATION LEVEL READ COMMITTED; args=None
2020-06-21 08:27:14,686 [uWSGIWorker3Core0:139737293428224] [django.db.backends:110] [utils:execute] [DEBUG]- (0.002) SELECT `django_session`.`session_key`, `django_session`.`session_data`, `django_session`.`expire_date` FROM `django_session` WHERE (`django_session`.`expire_date` > '2020-06-21 08:27:14.682998' AND `django_session`.`session_key` = 'b9iwultyte977hm1pqjvmmpc03f8av7g'); args=('2020-06-21 08:27:14.682998', 'b9iwultyte977hm1pqjvmmpc03f8av7g')
2020-06-21 08:27:14,693 [uWSGIWorker3Core0:139737293428224] [django.db.backends:110] [utils:execute] [DEBUG]- (0.006) SELECT `auth_user`.`id`, `auth_user`.`password`, `auth_user`.`last_login`, `auth_user`.`is_superuser`, `auth_user`.`username`, `auth_user`.`first_name`, `auth_user`.`last_name`, `auth_user`.`email`, `auth_user`.`is_staff`, `auth_user`.`is_active`, `auth_user`.`date_joined` FROM `auth_user` WHERE `auth_user`.`id` = 1; args=(1,)
2020-06-21 08:27:14,696 [uWSGIWorker3Core0:139737293428224] [django.template:872] [base:_resolve_lookup] [DEBUG]- Exception while resolving variable 'name' in template 'unknown'.
Traceback (most recent call last):
  File "/root/Envs/haole-uumOUkom/lib/python3.6/site-packages/django/core/handlers/exception.py", line 34, in inner
    response = get_response(request)
  File "/root/Envs/haole-uumOUkom/lib/python3.6/site-packages/django/core/handlers/base.py", line 100, in _get_response
    resolver_match = resolver.resolve(request.path_info)
  File "/root/Envs/haole-uumOUkom/lib/python3.6/site-packages/django/urls/resolvers.py", line 558, in resolve
    raise Resolver404({'tried': tried, 'path': new_path})
django.urls.exceptions.Resolver404: {'tried': [[<URLResolver <URLPattern list> (admin:admin) 'admin/'>], [<URLResolver <module 'apps.home.urls' from './apps/home/urls.py'> (None:None) ''>, <URLPattern '' [name='home']>], [<URLResolver <module 'apps.home.urls' from './apps/home/urls.py'> (None:None) ''>, <URLPattern 'delete' [name='delete']>], [<URLResolver <module 'apps.detail.urls' from './apps/detail/urls.py'> (None:None) 'article/'>], [<URLPattern '^favicon.ico$'>]], 'path': 'template/default_pc/html/style/js/popper.min.js'}

During handling of the above exception, another exception occurred:

Traceback (most recent call last):
  File "/root/Envs/haole-uumOUkom/lib/python3.6/site-packages/django/template/base.py", line 829, in _resolve_lookup
    current = current[bit]
TypeError: 'URLResolver' object is not subscriptable

During handling of the above exception, another exception occurred:

Traceback (most recent call last):
  File "/root/Envs/haole-uumOUkom/lib/python3.6/site-packages/django/template/base.py", line 837, in _resolve_lookup
    current = getattr(current, bit)
AttributeError: 'URLResolver' object has no attribute 'name'

During handling of the above exception, another exception occurred:

Traceback (most recent call last):
  File "/root/Envs/haole-uumOUkom/lib/python3.6/site-packages/django/template/base.py", line 843, in _resolve_lookup
    current = current[int(bit)]
ValueError: invalid literal for int() with base 10: 'name'

During handling of the above exception, another exception occurred:

Traceback (most recent call last):
  File "/root/Envs/haole-uumOUkom/lib/python3.6/site-packages/django/template/base.py", line 850, in _resolve_lookup
    (bit, current))  # missing attribute
django.template.base.VariableDoesNotExist: Failed lookup for key [name] in <URLResolver <URLPattern list> (admin:admin) 'admin/'>
2020-06-21 08:27:14,696 [uWSGIWorker3Core0:139737293428224] [django.template:872] [base:_resolve_lookup] [DEBUG]- Exception while resolving variable 'name' in template 'unknown'.
Traceback (most recent call last):
  File "/root/Envs/haole-uumOUkom/lib/python3.6/site-packages/django/core/handlers/exception.py", line 34, in inner
    response = get_response(request)
  File "/root/Envs/haole-uumOUkom/lib/python3.6/site-packages/django/core/handlers/base.py", line 100, in _get_response
    resolver_match = resolver.resolve(request.path_info)
  File "/root/Envs/haole-uumOUkom/lib/python3.6/site-packages/django/urls/resolvers.py", line 558, in resolve
    raise Resolver404({'tried': tried, 'path': new_path})
django.urls.exceptions.Resolver404: {'tried': [[<URLResolver <URLPattern list> (admin:admin) 'admin/'>], [<URLResolver <module 'apps.home.urls' from './apps/home/urls.py'> (None:None) ''>, <URLPattern '' [name='home']>], [<URLResolver <module 'apps.home.urls' from './apps/home/urls.py'> (None:None) ''>, <URLPattern 'delete' [name='delete']>], [<URLResolver <module 'apps.detail.urls' from './apps/detail/urls.py'> (None:None) 'article/'>], [<URLPattern '^favicon.ico$'>]], 'path': 'template/default_pc/html/style/js/popper.min.js'}

During handling of the above exception, another exception occurred:

Traceback (most recent call last):
  File "/root/Envs/haole-uumOUkom/lib/python3.6/site-packages/django/template/base.py", line 829, in _resolve_lookup
    current = current[bit]
TypeError: 'URLResolver' object is not subscriptable

During handling of the above exception, another exception occurred:

Traceback (most recent call last):
  File "/root/Envs/haole-uumOUkom/lib/python3.6/site-packages/django/template/base.py", line 837, in _resolve_lookup
    current = getattr(current, bit)
AttributeError: 'URLResolver' object has no attribute 'name'

During handling of the above exception, another exception occurred:

Traceback (most recent call last):
  File "/root/Envs/haole-uumOUkom/lib/python3.6/site-packages/django/template/base.py", line 843, in _resolve_lookup
    current = current[int(bit)]
ValueError: invalid literal for int() with base 10: 'name'

During handling of the above exception, another exception occurred:

Traceback (most recent call last):
  File "/root/Envs/haole-uumOUkom/lib/python3.6/site-packages/django/template/base.py", line 850, in _resolve_lookup
    (bit, current))  # missing attribute
django.template.base.VariableDoesNotExist: Failed lookup for key [name] in <URLResolver <module 'apps.detail.urls' from './apps/detail/urls.py'> (None:None) 'article/'>
2020-06-21 08:27:14,763 [uWSGIWorker3Core0:139737293428224] [django.db.backends:110] [utils:execute] [DEBUG]- (0.000) SET SESSION TRANSACTION ISOLATION LEVEL READ COMMITTED; args=None
2020-06-21 08:27:14,765 [uWSGIWorker3Core0:139737293428224] [django.db.backends:110] [utils:execute] [DEBUG]- (0.002) SELECT `django_session`.`session_key`, `django_session`.`session_data`, `django_session`.`expire_date` FROM `django_session` WHERE (`django_session`.`expire_date` > '2020-06-21 08:27:14.759581' AND `django_session`.`session_key` = 'b9iwultyte977hm1pqjvmmpc03f8av7g'); args=('2020-06-21 08:27:14.759581', 'b9iwultyte977hm1pqjvmmpc03f8av7g')
2020-06-21 08:27:14,770 [uWSGIWorker3Core0:139737293428224] [django.db.backends:110] [utils:execute] [DEBUG]- (0.004) SELECT `auth_user`.`id`, `auth_user`.`password`, `auth_user`.`last_login`, `auth_user`.`is_superuser`, `auth_user`.`username`, `auth_user`.`first_name`, `auth_user`.`last_name`, `auth_user`.`email`, `auth_user`.`is_staff`, `auth_user`.`is_active`, `auth_user`.`date_joined` FROM `auth_user` WHERE `auth_user`.`id` = 1; args=(1,)
2020-06-21 08:27:14,780 [uWSGIWorker3Core0:139737293428224] [django.template:872] [base:_resolve_lookup] [DEBUG]- Exception while resolving variable 'name' in template 'unknown'.
Traceback (most recent call last):
  File "/root/Envs/haole-uumOUkom/lib/python3.6/site-packages/django/core/handlers/exception.py", line 34, in inner
    response = get_response(request)
  File "/root/Envs/haole-uumOUkom/lib/python3.6/site-packages/django/core/handlers/base.py", line 100, in _get_response
    resolver_match = resolver.resolve(request.path_info)
  File "/root/Envs/haole-uumOUkom/lib/python3.6/site-packages/django/urls/resolvers.py", line 558, in resolve
    raise Resolver404({'tried': tried, 'path': new_path})
django.urls.exceptions.Resolver404: {'tried': [[<URLResolver <URLPattern list> (admin:admin) 'admin/'>], [<URLResolver <module 'apps.home.urls' from './apps/home/urls.py'> (None:None) ''>, <URLPattern '' [name='home']>], [<URLResolver <module 'apps.home.urls' from './apps/home/urls.py'> (None:None) ''>, <URLPattern 'delete' [name='delete']>], [<URLResolver <module 'apps.detail.urls' from './apps/detail/urls.py'> (None:None) 'article/'>], [<URLPattern '^favicon.ico$'>]], 'path': 'template/default_pc/html/style/js/imagesloaded.pkgd.min.js'}

During handling of the above exception, another exception occurred:

Traceback (most recent call last):
  File "/root/Envs/haole-uumOUkom/lib/python3.6/site-packages/django/template/base.py", line 829, in _resolve_lookup
    current = current[bit]
TypeError: 'URLResolver' object is not subscriptable

During handling of the above exception, another exception occurred:

Traceback (most recent call last):
  File "/root/Envs/haole-uumOUkom/lib/python3.6/site-packages/django/template/base.py", line 837, in _resolve_lookup
    current = getattr(current, bit)
AttributeError: 'URLResolver' object has no attribute 'name'

During handling of the above exception, another exception occurred:

Traceback (most recent call last):
  File "/root/Envs/haole-uumOUkom/lib/python3.6/site-packages/django/template/base.py", line 843, in _resolve_lookup
    current = current[int(bit)]
ValueError: invalid literal for int() with base 10: 'name'

During handling of the above exception, another exception occurred:

Traceback (most recent call last):
  File "/root/Envs/haole-uumOUkom/lib/python3.6/site-packages/django/template/base.py", line 850, in _resolve_lookup
    (bit, current))  # missing attribute
django.template.base.VariableDoesNotExist: Failed lookup for key [name] in <URLResolver <URLPattern list> (admin:admin) 'admin/'>
2020-06-21 08:27:14,791 [uWSGIWorker3Core0:139737293428224] [django.template:872] [base:_resolve_lookup] [DEBUG]- Exception while resolving variable 'name' in template 'unknown'.
Traceback (most recent call last):
  File "/root/Envs/haole-uumOUkom/lib/python3.6/site-packages/django/core/handlers/exception.py", line 34, in inner
    response = get_response(request)
  File "/root/Envs/haole-uumOUkom/lib/python3.6/site-packages/django/core/handlers/base.py", line 100, in _get_response
    resolver_match = resolver.resolve(request.path_info)
  File "/root/Envs/haole-uumOUkom/lib/python3.6/site-packages/django/urls/resolvers.py", line 558, in resolve
    raise Resolver404({'tried': tried, 'path': new_path})
django.urls.exceptions.Resolver404: {'tried': [[<URLResolver <URLPattern list> (admin:admin) 'admin/'>], [<URLResolver <module 'apps.home.urls' from './apps/home/urls.py'> (None:None) ''>, <URLPattern '' [name='home']>], [<URLResolver <module 'apps.home.urls' from './apps/home/urls.py'> (None:None) ''>, <URLPattern 'delete' [name='delete']>], [<URLResolver <module 'apps.detail.urls' from './apps/detail/urls.py'> (None:None) 'article/'>], [<URLPattern '^favicon.ico$'>]], 'path': 'template/default_pc/html/style/js/imagesloaded.pkgd.min.js'}

During handling of the above exception, another exception occurred:

Traceback (most recent call last):
  File "/root/Envs/haole-uumOUkom/lib/python3.6/site-packages/django/template/base.py", line 829, in _resolve_lookup
    current = current[bit]
TypeError: 'URLResolver' object is not subscriptable

During handling of the above exception, another exception occurred:

Traceback (most recent call last):
  File "/root/Envs/haole-uumOUkom/lib/python3.6/site-packages/django/template/base.py", line 837, in _resolve_lookup
    current = getattr(current, bit)
AttributeError: 'URLResolver' object has no attribute 'name'

During handling of the above exception, another exception occurred:

Traceback (most recent call last):
  File "/root/Envs/haole-uumOUkom/lib/python3.6/site-packages/django/template/base.py", line 843, in _resolve_lookup
    current = current[int(bit)]
ValueError: invalid literal for int() with base 10: 'name'

During handling of the above exception, another exception occurred:

Traceback (most recent call last):
  File "/root/Envs/haole-uumOUkom/lib/python3.6/site-packages/django/template/base.py", line 850, in _resolve_lookup
    (bit, current))  # missing attribute
django.template.base.VariableDoesNotExist: Failed lookup for key [name] in <URLResolver <module 'apps.detail.urls' from './apps/detail/urls.py'> (None:None) 'article/'>
2020-06-21 08:27:14,856 [uWSGIWorker3Core0:139737293428224] [django.db.backends:110] [utils:execute] [DEBUG]- (0.000) SET SESSION TRANSACTION ISOLATION LEVEL READ COMMITTED; args=None
2020-06-21 08:27:14,857 [uWSGIWorker3Core0:139737293428224] [django.db.backends:110] [utils:execute] [DEBUG]- (0.001) SELECT `django_session`.`session_key`, `django_session`.`session_data`, `django_session`.`expire_date` FROM `django_session` WHERE (`django_session`.`expire_date` > '2020-06-21 08:27:14.854076' AND `django_session`.`session_key` = 'b9iwultyte977hm1pqjvmmpc03f8av7g'); args=('2020-06-21 08:27:14.854076', 'b9iwultyte977hm1pqjvmmpc03f8av7g')
2020-06-21 08:27:14,861 [uWSGIWorker3Core0:139737293428224] [django.db.backends:110] [utils:execute] [DEBUG]- (0.002) SELECT `auth_user`.`id`, `auth_user`.`password`, `auth_user`.`last_login`, `auth_user`.`is_superuser`, `auth_user`.`username`, `auth_user`.`first_name`, `auth_user`.`last_name`, `auth_user`.`email`, `auth_user`.`is_staff`, `auth_user`.`is_active`, `auth_user`.`date_joined` FROM `auth_user` WHERE `auth_user`.`id` = 1; args=(1,)
2020-06-21 08:27:14,868 [uWSGIWorker3Core0:139737293428224] [django.template:872] [base:_resolve_lookup] [DEBUG]- Exception while resolving variable 'name' in template 'unknown'.
Traceback (most recent call last):
  File "/root/Envs/haole-uumOUkom/lib/python3.6/site-packages/django/core/handlers/exception.py", line 34, in inner
    response = get_response(request)
  File "/root/Envs/haole-uumOUkom/lib/python3.6/site-packages/django/core/handlers/base.py", line 100, in _get_response
    resolver_match = resolver.resolve(request.path_info)
  File "/root/Envs/haole-uumOUkom/lib/python3.6/site-packages/django/urls/resolvers.py", line 558, in resolve
    raise Resolver404({'tried': tried, 'path': new_path})
django.urls.exceptions.Resolver404: {'tried': [[<URLResolver <URLPattern list> (admin:admin) 'admin/'>], [<URLResolver <module 'apps.home.urls' from './apps/home/urls.py'> (None:None) ''>, <URLPattern '' [name='home']>], [<URLResolver <module 'apps.home.urls' from './apps/home/urls.py'> (None:None) ''>, <URLPattern 'delete' [name='delete']>], [<URLResolver <module 'apps.detail.urls' from './apps/detail/urls.py'> (None:None) 'article/'>], [<URLPattern '^favicon.ico$'>]], 'path': 'template/default_pc/html/style/js/bootstrap-paginator.js'}

During handling of the above exception, another exception occurred:

Traceback (most recent call last):
  File "/root/Envs/haole-uumOUkom/lib/python3.6/site-packages/django/template/base.py", line 829, in _resolve_lookup
    current = current[bit]
TypeError: 'URLResolver' object is not subscriptable

During handling of the above exception, another exception occurred:

Traceback (most recent call last):
  File "/root/Envs/haole-uumOUkom/lib/python3.6/site-packages/django/template/base.py", line 837, in _resolve_lookup
    current = getattr(current, bit)
AttributeError: 'URLResolver' object has no attribute 'name'

During handling of the above exception, another exception occurred:

Traceback (most recent call last):
  File "/root/Envs/haole-uumOUkom/lib/python3.6/site-packages/django/template/base.py", line 843, in _resolve_lookup
    current = current[int(bit)]
ValueError: invalid literal for int() with base 10: 'name'

During handling of the above exception, another exception occurred:

Traceback (most recent call last):
  File "/root/Envs/haole-uumOUkom/lib/python3.6/site-packages/django/template/base.py", line 850, in _resolve_lookup
    (bit, current))  # missing attribute
django.template.base.VariableDoesNotExist: Failed lookup for key [name] in <URLResolver <URLPattern list> (admin:admin) 'admin/'>
2020-06-21 08:27:14,869 [uWSGIWorker3Core0:139737293428224] [django.template:872] [base:_resolve_lookup] [DEBUG]- Exception while resolving variable 'name' in template 'unknown'.
Traceback (most recent call last):
  File "/root/Envs/haole-uumOUkom/lib/python3.6/site-packages/django/core/handlers/exception.py", line 34, in inner
    response = get_response(request)
  File "/root/Envs/haole-uumOUkom/lib/python3.6/site-packages/django/core/handlers/base.py", line 100, in _get_response
    resolver_match = resolver.resolve(request.path_info)
  File "/root/Envs/haole-uumOUkom/lib/python3.6/site-packages/django/urls/resolvers.py", line 558, in resolve
    raise Resolver404({'tried': tried, 'path': new_path})
django.urls.exceptions.Resolver404: {'tried': [[<URLResolver <URLPattern list> (admin:admin) 'admin/'>], [<URLResolver <module 'apps.home.urls' from './apps/home/urls.py'> (None:None) ''>, <URLPattern '' [name='home']>], [<URLResolver <module 'apps.home.urls' from './apps/home/urls.py'> (None:None) ''>, <URLPattern 'delete' [name='delete']>], [<URLResolver <module 'apps.detail.urls' from './apps/detail/urls.py'> (None:None) 'article/'>], [<URLPattern '^favicon.ico$'>]], 'path': 'template/default_pc/html/style/js/bootstrap-paginator.js'}

During handling of the above exception, another exception occurred:

Traceback (most recent call last):
  File "/root/Envs/haole-uumOUkom/lib/python3.6/site-packages/django/template/base.py", line 829, in _resolve_lookup
    current = current[bit]
TypeError: 'URLResolver' object is not subscriptable

During handling of the above exception, another exception occurred:

Traceback (most recent call last):
  File "/root/Envs/haole-uumOUkom/lib/python3.6/site-packages/django/template/base.py", line 837, in _resolve_lookup
    current = getattr(current, bit)
AttributeError: 'URLResolver' object has no attribute 'name'

During handling of the above exception, another exception occurred:

Traceback (most recent call last):
  File "/root/Envs/haole-uumOUkom/lib/python3.6/site-packages/django/template/base.py", line 843, in _resolve_lookup
    current = current[int(bit)]
ValueError: invalid literal for int() with base 10: 'name'

During handling of the above exception, another exception occurred:

Traceback (most recent call last):
  File "/root/Envs/haole-uumOUkom/lib/python3.6/site-packages/django/template/base.py", line 850, in _resolve_lookup
    (bit, current))  # missing attribute
django.template.base.VariableDoesNotExist: Failed lookup for key [name] in <URLResolver <module 'apps.detail.urls' from './apps/detail/urls.py'> (None:None) 'article/'>
